Workbook

Sheet 项目规划
A1: 做一个表，分周期，比如做雕牌这个项目，前期中期后期，也就是启动期间，盈利期间，放大期间，每个期间的总预算多少，冷启动一定是亏损吗，然后怎么在最短时间用最少的钱撬更大的回报； 减少亏损就是在前期中期后期这个总预算怎么分配各个环节

Sheet 公式表
A1: 销售额 = | B1: 订单数 × 客单价
A2: 销售额= | B2: 展现量 × 点击率 × 转化率 × 客单价
A3: 点击率 | B3: 广告素材被点击的次数占展示次数的百分比。计算方法：点击次数/展示次数*100%
A4: cpm | B4: 广告平均每一千次展现的费用，计算公式是：总花费/展示数*1000。
A5: 点击单价 | B5: 广告主为每次点击付出的费用成本，计算公式是：总花费/点击数
A6: 转化率 | B6: 广告转化数/广告被用户点击的次数，反应计划转化能力
A7: 单次曝光成本 | B7: 消耗 / 曝光数量
A8: 单次观看成本 | B8: 消耗 / 观看次数
A9: 曝光观看率 | B9: 观看次数 / 曝光次数
A10: UV价值 = | B10: (直播间销售额 / 直播间访客数)× 100%

Sheet 每日转化数据
A1: 序号 | B1: 日期 | C1: 主播 | D1: 当天 总销售 | E1: 直播时长 | F1: 总花费 | G1: 总投产 | H1: 总投产 （去退款） | I1: 观看 人次 | J1: 当天 退款金额 | K1: 实际 销售额 | L1: 退款占比 | M1: 杭州统计数据copy | V1: 粉丝统计 | AC1: 日常花费
M2: 直播进入率 | N2: 直播互动率 | O2: 停留时长 | P2: 观看转化率 | Q2: 投放流量占比 | R2: 投放流量成交金额占比 | S2: uv值 | T2: 增粉数量 | U2: 关注率 | V2: 昨天粉丝量（万） | W2: 当天粉丝量（万） | X2: 粉丝增加量（万） | Y2: 推广 涨粉 | Z2: 昨天粉丝团量（万） | AA2: 当天粉丝团量（万） | AB2: 粉丝团增加量（万） | AC2: 推广花费 | AD2: 礼物支出 | AE2: 粉丝福利
A3: 1 | B3: 45477 | D3: 2022 | E3: 6 | F3: =AC3+AD3+AE3 -> 1179.27 | G3: =D3/F3 -> 1.7146201 | H3: =K3/F3 -> 1.6468663 | I3: 3356 | J3: =VLOOKUP(B3,推广数据统计!$A:$AB,23,FALSE) -> 79.9 | K3: =D3-J3 -> 1942.1 | L3: =J3/D3 -> 0.039515331 | M3: 0.1135 | N3: 0.1431 | O3: 114 | P3: 0.0098 | Q3: 0.2011 | R3: 0.2108 | S3: 0.6 | T3: 177 | U3: 0.0527 | V3: 0 | W3: 1 | X3: =W3-V3 -> 1 | Y3: =推广数据统计!AB4 -> 16 | AA3: 4.7 | AB3: 0.1259 | AC3: =推广数据统计!B4+推广数据统计!AS4+推广数据统计!AV4+推广数据统计!BA4+推广数据统计!BF4 -> 1179.27
A4: 2 | B4: 45478 | D4: 986 | E4: 6 | F4: =AC4+AD4+AE4 -> 1182.97 | G4: =D4/F4 -> 0.83349535 | H4: =K4/F4 -> 0.83180469 | I4: 8519 | J4: =VLOOKUP(B4,推广数据统计!$A:$AB,23,FALSE) -> 2 | K4: =D4-J4 -> 984 | L4: =J4/D4 -> 0.0020283976 | M4: 0.2162 | N4: 0.1943 | O4: 97 | P4: 0.0013 | Q4: 0.0715 | R4: 0.3062 | S4: 0.12 | T4: 1112 | U4: 0.1305 | V4: =W3 -> 1 | X4: =W4-V4 -> -1 | Y4: =推广数据统计!AB5 -> 20 | AA4: 5.4 | AB4: =AA4-AA3 -> 0.7 | AC4: =推广数据统计!B5+推广数据统计!AS5+推广数据统计!AV5+推广数据统计!BA5+推广数据统计!BF5 -> 1182.97
A5: 3 | B5: 45479 | D5: 3143 | E5: 6 | F5: =AC5+AD5+AE5 -> 4404.98 | G5: =D5/F5 -> 0.71351062 | H5: =K5/F5 -> 0.66593038 | I5: 6038 | J5: =VLOOKUP(B5,推广数据统计!$A:$AB,23,FALSE) -> 209.59 | K5: =D5-J5 -> 2933.41 | L5: =J5/D5 -> 0.066684696 | M5: 0.1238 | N5: 0.1417 | O5: 104 | P5: 0.0096 | Q5: 0.3265 | R5: 0.8729 | S5: 0.52 | T5: 357 | U5: 0.0591 | V5: =W4 -> 0 | X5: =W5-V5 -> 0 | Y5: =推广数据统计!AB6 -> 27 | AA5: 4.9 | AB5: =AA5-AA4 -> -0.5 | AC5: =推广数据统计!B6+推广数据统计!AS6+推广数据统计!AV6+推广数据统计!BA6+推广数据统计!BF6 -> 4404.98
A6: 4 | B6: 45480 | D6: 8441 | E6: 6 | F6: =AC6+AD6+AE6 -> 7301.95 | G6: =D6/F6 -> 1.1559926 | H6: =K6/F6 -> 0.98435349 | I6: 6741 | J6: =VLOOKUP(B6,推广数据统计!$A:$AB,23,FALSE) -> 1253.3 | K6: =D6-J6 -> 7187.7 | L6: =J6/D6 -> 0.14847767 | M6: 0.0567 | N6: 0.1107 | O6: 82 | P6: 0.0156 | Q6: 0.4825 | R6: 0.8942 | S6: 1.25 | T6: 253 | U6: 0.0375 | Y6: =推广数据统计!AB7 -> 68 | AC6: =推广数据统计!B7+推广数据统计!AS7+推广数据统计!AV7+推广数据统计!BA7+推广数据统计!BF7 -> 7301.95
A7: 5 | B7: 45481 | D7: 10626 | E7: 6 | F7: =AC7+AD7+AE7 -> 8571.11 | G7: =D7/F7 -> 1.2397461 | H7: =K7/F7 -> 1.0343958 | I7: 10400 | J7: =VLOOKUP(B7,推广数据统计!$A:$AB,23,FALSE) -> 1760.08 | K7: =D7-J7 -> 8865.92 | L7: =J7/D7 -> 0.165639 | M7: 0.1036 | N7: 0.0216 | O7: 79 | P7: 0.0124 | Q7: 0.961 | R7: 0.9828 | S7: 1.02 | T7: 684 | U7: 0.0658 | Y7: =推广数据统计!AB8 -> 102 | AC7: =推广数据统计!B8+推广数据统计!AS8+推广数据统计!AV8+推广数据统计!BA8+推广数据统计!BF8 -> 8571.11
A8: 6 | B8: 45482 | D8: 6390 | E8: 6 | F8: =AC8+AD8+AE8 -> 5864.2 | G8: =D8/F8 -> 1.0896627 | H8: =K8/F8 -> 0.96072781 | I8: 7305 | J8: =VLOOKUP(B8,推广数据统计!$A:$AB,23,FALSE) -> 756.1 | K8: =D8-J8 -> 5633.9 | L8: =J8/D8 -> 0.11832551 | M8: 0.1089 | N8: 0.137 | O8: 76 | P8: 0.0102 | Q8: 0.3461 | R8: 0.883 | S8: 0.87 | T8: 405 | U8: 0.0554 | Y8: =推广数据统计!AB9 -> 52 | AC8: =推广数据统计!B9+推广数据统计!AS9+推广数据统计!AV9+推广数据统计!BA9+推广数据统计!BF9 -> 5864.2
A9: 7 | B9: 45483 | D9: 4047 | E9: 6 | F9: =AC9+AD9+AE9 -> 3319.62 | G9: =D9/F9 -> 1.2191154 | H9: =K9/F9 -> 1.1153686 | I9: 5481 | J9: =VLOOKUP(B9,推广数据统计!$A:$AB,23,FALSE) -> 344.4 | K9: =D9-J9 -> 3702.6 | L9: =J9/D9 -> 0.085100074 | M9: 0.1403 | N9: 0.1991 | O9: 93 | P9: 0.0089 | Q9: 0.2402 | R9: 0.7708 | S9: 0.74 | T9: 392 | U9: 0.0715 | Y9: =推广数据统计!AB10 -> 27 | AC9: =推广数据统计!B10+推广数据统计!AS10+推广数据统计!AV10+推广数据统计!BA10+推广数据统计!BF10 -> 3319.62
A10: 8 | B10: 45484 | D10: 8894 | E10: 6 | F10: =AC10+AD10+AE10 -> 7189.59 | G10: =D10/F10 -> 1.2370664 | H10: =K10/F10 -> 1.1426243 | I10: 11700 | J10: =VLOOKUP(B10,推广数据统计!$A:$AB,23,FALSE) -> 679 | K10: =D10-J10 -> 8215 | L10: =J10/D10 -> 0.076343602 | M10: 0.1543 | N10: 0.1613 | O10: 66 | P10: 0.0089 | Q10: 0.244 | R10: 0.9176 | S10: 0.76 | T10: 1001 | U10: 0.0856 | Y10: =推广数据统计!AB11 -> 53 | AC10: =推广数据统计!B11+推广数据统计!AS11+推广数据统计!AV11+推广数据统计!BA11+推广数据统计!BF11 -> 7189.59
A11: 9 | B11: 45485 | D11: 9502.53 | E11: 8 | F11: =AC11+AD11+AE11 -> 12332.54 | G11: =D11/F11 -> 0.77052497 | H11: =K11/F11 -> 0.66454518 | I11: 16800 | J11: =VLOOKUP(B11,推广数据统计!$A:$AB,23,FALSE) -> 1307 | K11: =D11-J11 -> 8195.53 | L11: =J11/D11 -> 0.13754232 | M11: 0.1954 | N11: 0.1689 | O11: 71 | P11: 0.0099 | Q11: 0.2568 | R11: 0.9067 | S11: 0.57 | T11: 1382 | U11: 0.0823 | Y11: =推广数据统计!AB12 -> 76 | AC11: =推广数据统计!B12+推广数据统计!AS12+推广数据统计!AV12+推广数据统计!BA12+推广数据统计!BF12 -> 12332.54
A12: 10 | B12: 45486 | D12: 11033.23 | E12: 8 | F12: =AC12+AD12+AE12 -> 14375.14 | G12: =D12/F12 -> 0.76752157 | H12: =K12/F12 -> 0.66261755 | I12: 18100 | J12: =VLOOKUP(B12,推广数据统计!$A:$AB,23,FALSE) -> 1508.01 | K12: =D12-J12 -> 9525.22 | L12: =J12/D12 -> 0.13667892 | M12: 0.1725 | N12: 0.1584 | O12: 78 | P12: 0.0105 | Q12: 0.2282 | R12: 0.924 | S12: 0.6 | T12: 1236 | U12: 0.0706 | Y12: =推广数据统计!AB13 -> 83 | AC12: =推广数据统计!B13+推广数据统计!AS13+推广数据统计!AV13+推广数据统计!BA13+推广数据统计!BF13 -> 14375.14
A13: 11 | B13: 45487 | D13: 12922.9 | E13: 8 | F13: =AC13+AD13+AE13 -> 8804.79 | G13: =D13/F13 -> 1.4677125 | H13: =K13/F13 -> 1.3267903 | I13: 14600 | J13: =VLOOKUP(B13,推广数据统计!$A:$AB,23,FALSE) -> 1240.79 | K13: =D13-J13 -> 11682.11 | L13: =J13/D13 -> 0.096014826 | M13: 0.2297 | N13: 0.1634 | O13: 92 | P13: 0.0107 | Q13: 0.2204 | R13: 0.9033 | S13: 0.6 | T13: 933 | U13: 0.156 | Y13: =推广数据统计!AB14 -> 78 | AC13: =推广数据统计!B14+推广数据统计!AS14+推广数据统计!AV14+推广数据统计!BA14+推广数据统计!BF14 -> 8804.79
A14: 12 | B14: 45488 | D14: 16935.07 | E14: 8 | F14: =AC14+AD14+AE14 -> 17859.94 | G14: =D14/F14 -> 0.94821539 | H14: =K14/F14 -> 0.82582528 | I14: 26800 | J14: =VLOOKUP(B14,推广数据统计!$A:$AB,23,FALSE) -> 2185.88 | K14: =D14-J14 -> 14749.19 | L14: =J14/D14 -> 0.12907416 | M14: 0.1641 | N14: 0.1368 | O14: 70 | P14: 0.0096 | Q14: 0.3073 | R14: 0.9218 | S14: 0.6 | T14: 1710 | U14: 0.156 | Y14: =推广数据统计!AB15 -> 171 | AC14: =推广数据统计!B15+推广数据统计!AS15+推广数据统计!AV15+推广数据统计!BA15+推广数据统计!BF15 -> 17859.94
A15: 13 | B15: 45489 | D15: 14593.52 | E15: 8 | F15: =AC15+AD15+AE15 -> 15583.28 | G15: =D15/F15 -> 0.93648577 | H15: =K15/F15 -> 0.86965838 | I15: 22800 | J15: =VLOOKUP(B15,推广数据统计!$A:$AB,23,FALSE) -> 1041.39 | K15: =D15-J15 -> 13552.13 | L15: =J15/D15 -> 0.071359754 | M15: 0.2001 | N15: 0.1469 | O15: 80 | P15: 0.0104 | Q15: 0.3008 | R15: 0.9582 | S15: 0.64 | T15: 1250 | U15: 0.1824 | Y15: =推广数据统计!AB16 -> 144 | AC15: =推广数据统计!B16+推广数据统计!AS16+推广数据统计!AV16+推广数据统计!BA16+推广数据统计!BF16 -> 15583.28
A16: 14 | B16: 45490 | F16: =AC16+AD16+AE16 -> 24579.49 | G16: =D16/F16 -> 0 | H16: =K16/F16 -> -0.11033549 | J16: =VLOOKUP(B16,推广数据统计!$A:$AB,23,FALSE) -> 2711.99 | K16: =D16-J16 -> -2711.99 | L16: =J16/D16 -> #DIV/0! | Y16: =推广数据统计!AB17 -> 166 | AC16: =推广数据统计!B17+推广数据统计!AS17+推广数据统计!AV17+推广数据统计!BA17+推广数据统计!BF17 -> 24579.49
A17: 15 | B17: 45491 | F17: =AC17+AD17+AE17 -> 32817.03 | G17: =D17/F17 -> 0 | H17: =K17/F17 -> -0.081530535 | J17: =VLOOKUP(B17,推广数据统计!$A:$AB,23,FALSE) -> 2675.59 | K17: =D17-J17 -> -2675.59 | L17: =J17/D17 -> #DIV/0! | Y17: =推广数据统计!AB18 -> 174 | AC17: =推广数据统计!B18+推广数据统计!AS18+推广数据统计!AV18+推广数据统计!BA18+推广数据统计!BF18 -> 32817.03
A18: 16 | B18: 45492 | F18: =AC18+AD18+AE18 -> 44176.17 | G18: =D18/F18 -> 0 | H18: =K18/F18 -> -0.082532279 | J18: =VLOOKUP(B18,推广数据统计!$A:$AB,23,FALSE) -> 3645.96 | K18: =D18-J18 -> -3645.96 | L18: =J18/D18 -> #DIV/0! | Y18: =推广数据统计!AB19 -> 274 | AC18: =推广数据统计!B19+推广数据统计!AS19+推广数据统计!AV19+推广数据统计!BA19+推广数据统计!BF19 -> 44176.17
A19: 17 | B19: 45493 | F19: =AC19+AD19+AE19 -> 54941.68 | G19: =D19/F19 -> 0 | H19: =K19/F19 -> -0.088034621 | J19: =VLOOKUP(B19,推广数据统计!$A:$AB,23,FALSE) -> 4836.77 | K19: =D19-J19 -> -4836.77 | L19: =J19/D19 -> #DIV/0! | Y19: =推广数据统计!AB20 -> 335 | AC19: =推广数据统计!B20+推广数据统计!AS20+推广数据统计!AV20+推广数据统计!BA20+推广数据统计!BF20 -> 54941.68
A20: 18 | B20: 45494 | F20: =AC20+AD20+AE20 -> 54227.93 | G20: =D20/F20 -> 0 | H20: =K20/F20 -> -0.093625923 | J20: =VLOOKUP(B20,推广数据统计!$A:$AB,23,FALSE) -> 5077.14 | K20: =D20-J20 -> -5077.14 | L20: =J20/D20 -> #DIV/0! | Y20: =推广数据统计!AB21 -> 298 | AC20: =推广数据统计!B21+推广数据统计!AS21+推广数据统计!AV21+推广数据统计!BA21+推广数据统计!BF21 -> 54227.93
A21: 19 | B21: 45495 | F21: =AC21+AD21+AE21 -> 46829.93 | G21: =D21/F21 -> 0 | H21: =K21/F21 -> -0.11025171 | J21: =VLOOKUP(B21,推广数据统计!$A:$AB,23,FALSE) -> 5163.08 | K21: =D21-J21 -> -5163.08 | L21: =J21/D21 -> #DIV/0! | Y21: =推广数据统计!AB22 -> 310 | AC21: =推广数据统计!B22+推广数据统计!AS22+推广数据统计!AV22+推广数据统计!BA22+推广数据统计!BF22 -> 46829.93
A22: 20 | B22: 45496 | F22: =AC22+AD22+AE22 -> 34116.2 | G22: =D22/F22 -> 0 | H22: =K22/F22 -> -0.088223776 | J22: =VLOOKUP(B22,推广数据统计!$A:$AB,23,FALSE) -> 3009.86 | K22: =D22-J22 -> -3009.86 | L22: =J22/D22 -> #DIV/0! | Y22: =推广数据统计!AB23 -> 227 | AC22: =推广数据统计!B23+推广数据统计!AS23+推广数据统计!AV23+推广数据统计!BA23+推广数据统计!BF23 -> 34116.2
A23: 21 | B23: 45497 | F23: =AC23+AD23+AE23 -> 25385.6 | G23: =D23/F23 -> 0 | H23: =K23/F23 -> -0.10756846 | J23: =VLOOKUP(B23,推广数据统计!$A:$AB,23,FALSE) -> 2730.69 | K23: =D23-J23 -> -2730.69 | L23: =J23/D23 -> #DIV/0! | Y23: =推广数据统计!AB24 -> 134 | AC23: =推广数据统计!B24+推广数据统计!AS24+推广数据统计!AV24+推广数据统计!BA24+推广数据统计!BF24 -> 25385.6
A24: 22 | B24: 45498 | F24: =AC24+AD24+AE24 -> 17794.57 | G24: =D24/F24 -> 0 | H24: =K24/F24 -> -0.076691373 | J24: =VLOOKUP(B24,推广数据统计!$A:$AB,23,FALSE) -> 1364.69 | K24: =D24-J24 -> -1364.69 | L24: =J24/D24 -> #DIV/0! | Y24: =推广数据统计!AB25 -> 82 | AC24: =推广数据统计!B25+推广数据统计!AS25+推广数据统计!AV25+推广数据统计!BA25+推广数据统计!BF25 -> 17794.57
A25: 23 | B25: 45499 | F25: =AC25+AD25+AE25 -> 0 | G25: =D25/F25 -> #DIV/0! | H25: =K25/F25 -> #DIV/0! | J25: =VLOOKUP(B25,推广数据统计!$A:$AB,23,FALSE) -> 0 | K25: =D25-J25 -> 0 | L25: =J25/D25 -> #DIV/0! | Y25: =推广数据统计!AB26 -> 4 | AC25: =推广数据统计!B26+推广数据统计!AS26+推广数据统计!AV26+推广数据统计!BA26+推广数据统计!BF26 -> 0
A26: 24 | B26: 45500 | F26: =AC26+AD26+AE26 -> 0 | G26: =D26/F26 -> #DIV/0! | H26: =K26/F26 -> #DIV/0! | J26: =VLOOKUP(B26,推广数据统计!$A:$AB,23,FALSE) -> 0 | K26: =D26-J26 -> 0 | L26: =J26/D26 -> #DIV/0! | Y26: =推广数据统计!AB27 -> 1 | AC26: =推广数据统计!B27+推广数据统计!AS27+推广数据统计!AV27+推广数据统计!BA27+推广数据统计!BF27 -> 0
A27: 25 | B27: 45501 | F27: =AC27+AD27+AE27 -> 0 | G27: =D27/F27 -> #DIV/0! | H27: =K27/F27 -> #DIV/0! | J27: =VLOOKUP(B27,推广数据统计!$A:$AB,23,FALSE) -> 0 | K27: =D27-J27 -> 0 | L27: =J27/D27 -> #DIV/0! | Y27: =推广数据统计!AB28 -> 2 | AC27: =推广数据统计!B28+推广数据统计!AS28+推广数据统计!AV28+推广数据统计!BA28+推广数据统计!BF28 -> 0
... A29: 27 | B29: 45503 | F29: =AC29+AD29+AE29 -> 44332.69 | G29: =D29/F29 -> 0 | H29: =K29/F29 -> -0.096360496 | J29: =VLOOKUP(B29,推广数据统计!$A:$AB,23,FALSE) -> 4271.92 | K29: =D29-J29 -> -4271.92 | L29: =J29/D29 -> #DIV/0! | Y29: =推广数据统计!AB30 -> 230 | AC29: =推广数据统计!B30+推广数据统计!AS30+推广数据统计!AV30+推广数据统计!BA30+推广数据统计!BF30 -> 44332.69
A30: 28 | B30: 45504 | D30: 25228 | E30: 12 | F30: =AC30+AD30+AE30 -> 23709.37 | G30: =D30/F30 -> 1.0640519 | H30: =K30/F30 -> 0.98299533 | I30: 23700 | J30: =VLOOKUP(B30,推广数据统计!$A:$AB,23,FALSE) -> 1921.8 | K30: =D30-J30 -> 23306.2 | L30: =J30/D30 -> 0.076177263 | M30: 0.1417 | N30: 0.2303 | O30: 111 | P30: 0.013 | Q30: 0.2037 | R30: 0.9182 | S30: 1.06 | T30: 997 | U30: 0.042 | Y30: =推广数据统计!AB31 -> 96 | AC30: =推广数据统计!B31+推广数据统计!AS31+推广数据统计!AV31+推广数据统计!BA31+推广数据统计!BF31 -> 23709.37
A31: 29 | B31: 45505 | D31: 26075.59 | E31: 12 | F31: =AC31+AD31+AE31 -> 21600.16 | G31: =D31/F31 -> 1.2071943 | H31: =K31/F31 -> 1.1079126 | I31: 21800 | J31: =VLOOKUP(B31,推广数据统计!$A:$AB,23,FALSE) -> 2144.5 | K31: =D31-J31 -> 23931.09 | L31: =J31/D31 -> 0.082241667 | M31: 0.1349 | N31: 0.2213 | O31: 115 | P31: 0.0147 | Q31: 0.2298 | R31: 0.9273 | S31: 1.2 | T31: 882 | U31: 0.04 | Y31: =推广数据统计!AB32 -> 108 | AC31: =推广数据统计!B32+推广数据统计!AS32+推广数据统计!AV32+推广数据统计!BA32+推广数据统计!BF32 -> 21600.16
A32: 30 | B32: 45506 | D32: 48396.55 | E32: 12 | F32: =AC32+AD32+AE32 -> 38257.64 | G32: =D32/F32 -> 1.2650166 | H32: =K32/F32 -> 1.1574475 | I32: 29000 | J32: =VLOOKUP(B32,推广数据统计!$A:$AB,23,FALSE) -> 4115.34 | K32: =D32-J32 -> 44281.21 | L32: =J32/D32 -> 0.085033747 | M32: 0.0991 | N32: 0.1887 | O32: 97 | P32: 0.0206 | Q32: 0.3414 | R32: 0.9498 | S32: 1.67 | T32: 1272 | U32: 0.043 | Y32: =推广数据统计!AB33 -> 210 | AC32: =推广数据统计!B33+推广数据统计!AS33+推广数据统计!AV33+推广数据统计!BA33+推广数据统计!BF33 -> 38257.64
A33: 31 | B33: 45507 | D33: 30718.92 | E33: 12 | F33: =AC33+AD33+AE33 -> 23669.17 | G33: =D33/F33 -> 1.2978453 | H33: =K33/F33 -> 1.1914748 | I33: 25600 | J33: =VLOOKUP(B33,推广数据统计!$A:$AB,23,FALSE) -> 2517.7 | K33: =D33-J33 -> 28201.22 | L33: =J33/D33 -> 0.081959262 | M33: 0.142 | N33: 0.2041 | O33: 102 | P33: 0.0145 | Q33: 0.3184 | R33: 0.9406 | S33: 0.83 | T33: 1186 | U33: 0.0463 | Y33: =推广数据统计!AB34 -> 186 | AC33: =推广数据统计!B34+推广数据统计!AS34+推广数据统计!AV34+推广数据统计!BA34+推广数据统计!BF34 -> 23669.17
A34: 32 | B34: 45508 | D34: 36422.74 | E34: 12 | F34: =AC34+AD34+AE34 -> 28453.73 | G34: =D34/F34 -> 1.2800691 | H34: =K34/F34 -> 1.1519323 | I34: 25400 | J34: =VLOOKUP(B34,推广数据统计!$A:$AB,23,FALSE) -> 3645.97 | K34: =D34-J34 -> 32776.77 | L34: =J34/D34 -> 0.10010148 | M34: 0.1327 | N34: 0.177 | O34: 96 | P34: 0.0176 | Q34: 0.4367 | R34: 0.8503 | S34: 1.43 | T34: 964 | U34: 0.038 | Y34: =推广数据统计!AB35 -> 192 | AC34: =推广数据统计!B35+推广数据统计!AS35+推广数据统计!AV35+推广数据统计!BA35+推广数据统计!BF35 -> 28453.73
A35: 33 | B35: 45509 | D35: 28869.95 | E35: 12 | F35: =AC35+AD35+AE35 -> 23735.73 | G35: =D35/F35 -> 1.2163077 | H35: =K35/F35 -> 1.1023322 | I35: 24400 | J35: =VLOOKUP(B35,推广数据统计!$A:$AB,23,FALSE) -> 2705.29 | K35: =D35-J35 -> 26164.66 | L35: =J35/D35 -> 0.093706085 | M35: 0.13 | N35: 0.2104 | O35: 108S | P35: 0.0143 | Q35: 0.2402 | R35: 0.9115 | S35: 1.18 | T35: 943 | U35: 0.0386 | Y35: =推广数据统计!AB36 -> 139 | AC35: =推广数据统计!B36+推广数据统计!AS36+推广数据统计!AV36+推广数据统计!BA36+推广数据统计!BF36 -> 23735.73
A36: 34 | B36: 45510 | D36: 86992.7 | E36: 18 | F36: =AC36+AD36+AE36 -> 70638.86 | G36: =D36/F36 -> 1.2315134 | H36: =K36/F36 -> 1.1218247 | I36: 68000 | J36: =VLOOKUP(B36,推广数据统计!$A:$AB,23,FALSE) -> 7748.28 | K36: =D36-J36 -> 79244.42 | L36: =J36/D36 -> 0.089068163 | M36: 0.06 | N36: 0.1209 | O36: 67 | P36: 0.0158 | Q36: 0.3547 | R36: 0.9139 | S36: 1.28 | T36: 2634 | U36: 0.0387 | Y36: =推广数据统计!AB37 -> 407 | AC36: =推广数据统计!B37+推广数据统计!AS37+推广数据统计!AV37+推广数据统计!BA37+推广数据统计!BF37 -> 70638.86
A37: 35 | B37: 45511 | C37: 小五 | D37: 670529 | E37: 18 | F37: =AC37+AD37+AE37 -> 586705.92 | G37: =D37/F37 -> 1.1428707 | H37: =K37/F37 -> 1.0017668 | I37: 440200 | J37: =VLOOKUP(B37,推广数据统计!$A:$AB,23,FALSE) -> 82786.5 | K37: =D37-J37 -> 587742.5 | L37: =J37/D37 -> 0.12346446 | M37: 0.05 | N37: 0.0341 | O37: 53 | P37: 0.0182 | Q37: 0.8444 | R37: 0.9363 | S37: 1.52 | T37: 6251 | U37: 0.0142 | Y37: =推广数据统计!AB38 -> 3588 | AC37: =推广数据统计!B38+推广数据统计!AS38+推广数据统计!AV38+推广数据统计!BA38+推广数据统计!BF38 -> 586705.92
A38: 36 | B38: 45512 | D38: 95408.99 | E38: 18 | F38: =AC38+AD38+AE38 -> 73848.19 | G38: =D38/F38 -> 1.2919611 | H38: =K38/F38 -> 1.1502366 | I38: 64000 | J38: =VLOOKUP(B38,推广数据统计!$A:$AB,23,FALSE) -> 10466.1 | K38: =D38-J38 -> 84942.89 | L38: =J38/D38 -> 0.10969721 | M38: 0.1043 | N38: 0.1191 | O38: 86s | P38: 0.0178 | Q38: 0.4901 | R38: 0.9261 | S38: 1.49 | T38: 1795 | U38: 0.0281 | Y38: =推广数据统计!AB39 -> 417 | AC38: =推广数据统计!B39+推广数据统计!AS39+推广数据统计!AV39+推广数据统计!BA39+推广数据统计!BF39 -> 73848.19
A39: 37 | B39: 45513 | D39: 160390 | E39: 18 | F39: =AC39+AD39+AE39 -> 127284.19 | G39: =D39/F39 -> 1.2600937 | H39: =K39/F39 -> 1.1255474 | I39: 65900 | J39: =VLOOKUP(B39,推广数据统计!$A:$AB,23,FALSE) -> 17125.61 | K39: =D39-J39 -> 143264.39 | L39: =J39/D39 -> 0.1067748 | M39: 0.086 | N39: 0.1111 | O39: 73 | P39: 0.029 | Q39: 0.5603 | R39: 0.9717 | S39: 2.43 | T39: 1759 | U39: 0.0281 | Y39: =推广数据统计!AB40 -> 578 | AC39: =推广数据统计!B40+推广数据统计!AS40+推广数据统计!AV40+推广数据统计!BA40+推广数据统计!BF40 -> 127284.19
A40: 38 | B40: 45514 | D40: 112430 | E40: 18 | F40: =AC40+AD40+AE40 -> 87943.24 | G40: =D40/F40 -> 1.2784382 | H40: =K40/F40 -> 1.1591668 | I40: 47700 | J40: =VLOOKUP(B40,推广数据统计!$A:$AB,23,FALSE) -> 10489.12 | K40: =D40-J40 -> 101940.88 | L40: =J40/D40 -> 0.093294672 | M40: 0.1013 | N40: 0.1291 | O40: 81 | P40: 0.0288 | Q40: 0.4851 | R40: 0.9621 | S40: 2.36 | T40: 1309 | U40: 0.0281 | Y40: =推广数据统计!AB41 -> 416 | AC40: =推广数据统计!B41+推广数据统计!AS41+推广数据统计!AV41+推广数据统计!BA41+推广数据统计!BF41 -> 87943.24
A41: 39 | B41: 45515 | D41: 160073 | E41: 18 | F41: =AC41+AD41+AE41 -> 118422.81 | G41: =D41/F41 -> 1.3517075 | H41: =K41/F41 -> 1.2075964 | I41: 68900 | J41: =VLOOKUP(B41,推广数据统计!$A:$AB,23,FALSE) -> 17066.04 | K41: =D41-J41 -> 143006.96 | L41: =J41/D41 -> 0.10661411 | M41: 0.1159 | N41: 0.1203 | O41: 96 | P41: 0.0273 | Q41: 0.7162 | R41: 0.9635 | S41: 2.32 | T41: 1400 | U41: 0.0203 | Y41: =推广数据统计!AB42 -> 539 | AC41: =推广数据统计!B42+推广数据统计!AS42+推广数据统计!AV42+推广数据统计!BA42+推广数据统计!BF42 -> 118422.81
...

Sheet 推广数据统计
A1: 推广数据统计
A2: 日期 | B2: 千川推广 | AS2: 抖+ | AV2: 随心推 | BA2: feedslive | BF2: 种草通
B3: 消耗 | C3: 展示次数 | D3: 点击率 | E3: 点击次数 | F3: 平均千次展现费用 | G3: 7日总支付ROI | H3: 7日总成交订单数 | I3: 7日总成交金额 | J3: 直接成交订单数 | K3: 直接成交金额 | L3: 成交智能优惠券金额 | M3: 直接支付ROI | N3: 点击单价 | O3: 转化数 | P3: 转化率 | Q3: 转化成本 | R3: 广告平均成交金额 | S3: 直播间观看人次 | T3: 有效看播数 | U3: 有效看播率 | V3: 有效看播成本 | W3: 直接退款金额（7天） | X3: 直接退款率(7天) | Y3: 直接成交金额结算率(7天) | Z3: 直接结算ROI(7天) | AA3: 直接结算成本（7天） | AB3: 涨粉量 | AC3: 涨粉成本 | AD3: 直播时长 | AE3: 平均在线人数 | AF3: 单次展示成本(曝光成本） | AG3: 观看单次成本（场观） | AH3: uv值 | AI3: 曝光观看率 | AJ3: 优惠券占比 | AK3: 观看-成交率 | AL3: 直投消耗 | AM3: 素材消耗 | AN3: 直投占比 | AO3: 素材占比 | AP3: 通投消耗 | AQ3: 搜索消耗 | AR3: 商品消耗 | AS3: 花费 | AT3: 涨粉量 | AU3: 涨粉成本 | AV3: 花费 | AW3: 涨粉量 | AX3: 涨粉成本 | AY3: 成交额 | AZ3: 投产 | BA3: 花费 | BB3: 涨粉量 | BC3: 涨粉成本 | BD3: 成交额 | BE3: 投产 | BF3: 花费 | BG3: 涨粉量 | BH3: 涨粉成本
A4: 45477 | B4: 1179.27 | C4: 13832 | D4: 0.0366 | E4: 506 | F4: 85.26 | G4: 1.22 | H4: 18 | I4: 937.2 | J4: 18 | K4: 937.2 | L4: 501 | M4: 1.22 | N4: 2.33 | O4: 18 | P4: 0.0356 | Q4: 65.52 | R4: 52.07 | S4: 493 | T4: 0 | U4: 0 | V4: 0 | W4: 79.9 | X4: 0.0853 | Y4: 0.9147 | Z4: 1.15 | AA4: 69.37 | AB4: 16 | AC4: =B4/AB4 -> 73.704375 | AF4: =B4/C4 -> 0.085256651 | AG4: =B4/S4 -> 2.3920284 | AH4: =(K4+L4)/S4 -> 2.9172414 | AI4: =S4/C4 -> 0.03564199 | AJ4: =L4/(K4+L4) -> 0.34835211 | AK4: {=O4·/S4} -> #NAME?
A5: 45478 | B5: 1182.97 | C5: 15957 | D5: 0.0495 | E5: 790 | F5: 74.13 | G5: 0.43 | H5: 10 | I5: 341.2 | J5: 7 | K5: 301.9 | L5: 167 | M5: 0.4 | N5: 1.5 | O5: 8 | P5: 0.0101 | Q5: 147.87 | R5: 43.13 | S5: 815 | T5: 0 | U5: 0 | V5: 0 | W5: 2 | X5: 0.0066 | Y5: 0.9934 | Z5: 0.37 | AA5: 197.16 | AB5: 20 | AC5: =B5/AB5 -> 59.1485 | AF5: =B5/C5 -> 0.074134862 | AG5: =B5/S5 -> 1.4514969 | AH5: =(K5+L5)/S5 -> 0.57533742 | AI5: =S5/C5 -> 0.051074763 | AJ5: =L5/(K5+L5) -> 0.3561527 | AK5: =O5/S5 -> 0.0098159509
A6: 45479 | B6: 4404.98 | C6: 67116 | D6: 0.036 | E6: 2416 | F6: 65.63 | G6: 0.9 | H6: 56 | I6: 2768.26 | J6: 54 | K6: 2743.56 | L6: 1193.04 | M6: 0.89 | N6: 1.82 | O6: 55 | P6: 0.0228 | Q6: 80.09 | R6: 50.81 | S6: 2570 | T6: 0 | U6: 0 | V6: 0 | W6: 209.59 | X6: 0.0764 | Y6: 0.9236 | Z6: 0.82 | AA6: 89.9 | AB6: 27 | AC6: =B6/AB6 -> 163.14741 | AF6: =B6/C6 -> 0.065632338 | AG6: =B6/S6 -> 1.714 | AH6: =(K6+L6)/S6 -> 1.531751 | AI6: =S6/C6 -> 0.038291913 | AJ6: =L6/(K6+L6) -> 0.30306356 | AK6: =O6/S6 -> 0.021400778
A7: 45480 | B7: 7301.95 | C7: 141175 | D7: 0.0294 | E7: 4155 | F7: 51.72 | G7: 1.09 | H7: 104 | I7: 5908.32 | J7: 102 | K7: 5827.42 | L7: 2050.98 | M7: 1.08 | N7: 1.76 | O7: 102 | P7: 0.0245 | Q7: 71.59 | R7: 57.13 | S7: 4262 | T7: 0 | U7: 0 | V7: 0 | W7: 1253.3 | X7: 0.2151 | Y7: 0.7849 | Z7: 0.86 | AA7: 93.61 | AB7: 68 | AC7: =B7/AB7 -> 107.38162 | AF7: =B7/C7 -> 0.051722685 | AG7: =B7/S7 -> 1.7132684 | AH7: =(K7+L7)/S7 -> 1.8485218 | AI7: =S7/C7 -> 0.030189481 | AJ7: =L7/(K7+L7) -> 0.26032951 | AK7: =O7/S7 -> 0.023932426
A8: 45481 | B8: 8571.11 | C8: 151559 | D8: 0.037 | E8: 5603 | F8: 56.55 | G8: 1.18 | H8: 129 | I8: 7974.41 | J8: 128 | K8: 7894.51 | L8: 2173.96 | M8: 1.17 | N8: 1.53 | O8: 128 | P8: 0.0228 | Q8: 66.96 | R8: 61.68 | S8: 5916 | T8: 0 | U8: 0 | V8: 0 | W8: 1760.08 | X8: 0.2229 | Y8: 0.7771 | Z8: 0.9 | AA8: 89.28 | AB8: 102 | AC8: =B8/AB8 -> 84.03049 | AF8: =B8/C8 -> 0.05655296 | AG8: =B8/S8 -> 1.4488016 | AH8: =(K8+L8)/S8 -> 1.701905 | AI8: =S8/C8 -> 0.039034303 | AJ8: =L8/(K8+L8) -> 0.21591761 | AK8: =O8/S8 -> 0.021636241
A9: 45482 | B9: 5864.2 | C9: 82729 | D9: 0.0423 | E9: 3496 | F9: 70.88 | G9: 1.01 | H9: 76 | I9: 4319.09 | J9: 74 | K9: 4221.39 | L9: 1610.01 | M9: 0.99 | N9: 1.68 | O9: 73 | P9: 0.0209 | Q9: 80.33 | R9: 57.05 | S9: 3443 | T9: 0 | U9: 0 | V9: 0 | W9: 756.1 | X9: 0.1791 | Y9: 0.8209 | Z9: 0.82 | AA9: 97.74 | AB9: 52 | AC9: =B9/AB9 -> 112.77308 | AF9: =B9/C9 -> 0.070884454 | AG9: =B9/S9 -> 1.7032239 | AH9: =(K9+L9)/S9 -> 1.6936974 | AI9: =S9/C9 -> 0.041617812 | AJ9: =L9/(K9+L9) -> 0.27609322 | AK9: =O9/S9 -> 0.02120244
A10: 45483 | B10: 3319.62 | C10: 42698 | D10: 0.0448 | E10: 1915 | F10: 77.75 | G10: 1.01 | H10: 42 | I10: 2418.39 | J10: 42 | K10: 2418.39 | L10: 934.01 | M10: 1.01 | N10: 1.73 | O10: 42 | P10: 0.0219 | Q10: 79.04 | R10: 57.58 | S10: 1953 | T10: 0 | U10: 0 | V10: 0 | W10: 344.4 | X10: 0.1424 | Y10: 0.8576 | Z10: 0.87 | AA10: 92.21 | AB10: 27 | AC10: =B10/AB10 -> 122.94889 | AF10: =B10/C10 -> 0.077746499 | AG10: =B10/S10 -> 1.6997542 | AH10: =(K10+L10)/S10 -> 1.7165387 | AI10: =S10/C10 -> 0.045739847 | AJ10: =L10/(K10+L10) -> 0.27860935 | AK10: =O10/S10 -> 0.021505376
A11: 45484 | B11: 7189.59 | C11: 95558 | D11: 0.0372 | E11: 3554 | F11: 75.24 | G11: 1.18 | H11: 106 | I11: 6392.57 | J11: 104 | K11: 6232.77 | L11: 2102.03 | M11: 1.16 | N11: 2.02 | O11: 105 | P11: 0.0295 | Q11: 68.47 | R11: 59.93 | S11: 3733 | T11: 0 | U11: 0 | V11: 0 | W11: 679 | X11: 0.1089 | Y11: 0.8911 | Z11: 1.03 | AA11: 78.15 | AB11: 53 | AC11: =B11/AB11 -> 135.65264 | AF11: =B11/C11 -> 0.075237971 | AG11: =B11/S11 -> 1.925955 | AH11: =(K11+L11)/S11 -> 2.2327351 | AI11: =S11/C11 -> 0.03906528 | AJ11: =L11/(K11+L11) -> 0.25219921 | AK11: =O11/S11 -> 0.028127511
A12: 45485 | B12: 12332.54 | C12: 150642 | D12: 0.0376 | E12: 5662 | F12: 81.87 | G12: 0.99 | H12: 158 | I12: 8711.83 | J12: 157 | K12: 8661.93 | L12: 3507.07 | M12: 0.99 | N12: 2.18 | O12: 155 | P12: 0.0274 | Q12: 79.56 | R12: 55.17 | S12: 6166 | T12: 0 | U12: 0 | V12: 0 | W12: 1307 | X12: 0.1509 | Y12: 0.8491 | Z12: 0.84 | AA12: 93.43 | AB12: 76 | AC12: =B12/AB12 -> 162.27026 | AF12: =B12/C12 -> 0.081866545 | AG12: =B12/S12 -> 2.0000876 | AH12: =(K12+L12)/S12 -> 1.9735647 | AI12: =S12/C12 -> 0.04093148 | AJ12: =L12/(K12+L12) -> 0.28819706 | AK12: =O12/S12 -> 0.025137853
A13: 45486 | B13: 14375.14 | C13: 183965 | D13: 0.0304 | E13: 5589 | F13: 78.14 | G13: 0.97 | H13: 185 | I13: 9953.73 | J13: 183 | K13: 9889.93 | L13: 3997.99 | M13: 0.97 | N13: 2.57 | O13: 183 | P13: 0.0327 | Q13: 78.55 | R13: 54.04 | S13: 5927 | T13: 0 | U13: 0 | V13: 0 | W13: 1508.01 | X13: 0.1525 | Y13: 0.8475 | Z13: 0.83 | AA13: 92.74 | AB13: 83 | AC13: =B13/AB13 -> 173.19446 | AF13: =B13/C13 -> 0.078140625 | AG13: =B13/S13 -> 2.4253653 | AH13: =(K13+L13)/S13 -> 2.3431618 | AI13: =S13/C13 -> 0.032218085 | AJ13: =L13/(K13+L13) -> 0.28787536 | AK13: =O13/S13 -> 0.030875654
A14: 45487 | B14: 8804.79 | C14: 124251 | D14: 0.0338 | E14: 4203 | F14: 70.86 | G14: 1.28 | H14: 146 | I14: 8654.65 | J14: 140 | K14: 8284.25 | L14: 2646.05 | M14: 1.24 | N14: 2.09 | O14: 138 | P14: 0.0328 | Q14: 63.8 | R14: 59.17 | S14: 4633 | T14: 0 | U14: 0 | V14: 0 | W14: 1240.79 | X14: 0.1498 | Y14: 0.8502 | Z14: 1.07 | AA14: 73.99 | AB14: 78 | AC14: =B14/AB14 -> 112.88192 | AF14: =B14/C14 -> 0.070862931 | AG14: =B14/S14 -> 1.9004511 | AH14: =(K14+L14)/S14 -> 2.3592273 | AI14: =S14/C14 -> 0.037287426 | AJ14: =L14/(K14+L14) -> 0.24208393 | AK14: =O14/S14 -> 0.029786316
A15: 45488 | B15: 17859.94 | C15: 323494 | D15: 0.0294 | E15: 9509 | F15: 55.21 | G15: 1.08 | H15: 247 | I15: 15725.07 | J15: 242 | K15: 15609.77 | L15: 3636.13 | M15: 1.08 | N15: 1.88 | O15: 244 | P15: 0.0257 | Q15: 73.2 | R15: 64.5 | S15: 11041 | T15: 0 | U15: 0 | V15: 0 | W15: 2185.88 | X15: 0.14 | Y15: 0.86 | Z15: 0.93 | AA15: 86.28 | AB15: 171 | AC15: =B15/AB15 -> 104.44409 | AF15: =B15/C15 -> 0.055209494 | AG15: =B15/S15 -> 1.6176017 | AH15: =(K15+L15)/S15 -> 1.7431302 | AI15: =S15/C15 -> 0.034130463 | AJ15: =L15/(K15+L15) -> 0.18893011 | AK15: =O15/S15 -> 0.022099448
A16: 45489 | B16: 15583.28 | C16: 202738 | D16: 0.0424 | E16: 8598 | F16: 76.86 | G16: 1.2 | H16: 234 | I16: 14275.52 | J16: 229 | K16: 13984.32 | L16: 4390.08 | M16: 1.18 | N16: 1.81 | O16: 230 | P16: 0.0268 | Q16: 67.75 | R16: 61.07 | S16: 9848 | T16: 0 | U16: 0 | V16: 0 | W16: 1041.39 | X16: 0.0745 | Y16: 0.9255 | Z16: 1.09 | AA16: 74.21 | AB16: 144 | AC16: =B16/AB16 -> 108.21722 | AF16: =B16/C16 -> 0.07686413 | AG16: =B16/S16 -> 1.5823802 | AH16: =(K16+L16)/S16 -> 1.8658002 | AI16: =S16/C16 -> 0.048575008 | AJ16: =L16/(K16+L16) -> 0.23892372 | AK16: =O16/S16 -> 0.023354996
... A31: 45504 | B31: 23709.37 | C31: 188999 | D31: 0.0384 | E31: 7267 | F31: 125.45 | G31: 1.01 | H31: 301 | I31: 15909.68 | J31: 297 | K31: 15818.78 | L31: 8043.02 | M31: 1.01 | N31: 3.26 | O31: 296 | P31: 0.0407 | Q31: 80.1 | R31: 53.26 | S31: 7877 | T31: 0 | U31: 0 | V31: 0 | W31: 1921.8 | X31: 0.1215 | Y31: 0.8785 | Z31: 0.88 | AA31: 92.98 | AB31: 96 | AC31: =B31/AB31 -> 246.9726 | AF31: =B31/C31 -> 0.12544707 | AG31: =B31/S31 -> 3.0099492 | AH31: =(K31+L31)/S31 -> 3.0293005 | AI31: =S31/C31 -> 0.041677469 | AJ31: =L31/(K31+L31) -> 0.33706678 | AK31: =O31/S31 -> 0.037577758
A32: 45505 | B32: 21600.16 | C32: 206272 | D32: 0.0372 | E32: 7677 | F32: 104.72 | G32: 1.16 | H32: 320 | I32: 16664.13 | J32: 310 | K32: 16426.23 | L32: 8411.96 | M32: 1.15 | N32: 2.81 | O32: 308 | P32: 0.0401 | Q32: 70.13 | R32: 52.99 | S32: 8352 | T32: 0 | U32: 0 | V32: 0 | W32: 2144.5 | X32: 0.1306 | Y32: 0.8694 | Z32: 1 | AA32: 81.2 | AB32: 108 | AC32: =B32/AB32 -> 200.00148 | AF32: =B32/C32 -> 0.10471688 | AG32: =B32/S32 -> 2.5862261 | AH32: =(K32+L32)/S32 -> 2.9739212 | AI32: =S32/C32 -> 0.040490226 | AJ32: =L32/(K32+L32) -> 0.33867041 | AK32: {=O32/·S32} -> #NAME?
A33: 45506 | B33: 38257.64 | C33: 376011 | D33: 0.0375 | E33: 14098 | F33: 101.75 | G33: 1.23 | H33: 595 | I33: 31440.84 | J33: 585 | K33: 30979.73 | L33: 15780.12 | M33: 1.22 | N33: 2.71 | O33: 1437 | P33: 0.1019 | Q33: 26.62 | R33: 52.96 | S33: 15480 | T33: 860 | U33: 0.4639 | V33: 0.83 | W33: 4115.34 | X33: 0.1328 | Y33: 0.8672 | Z33: 1.06 | AA33: 77.13 | AB33: 210 | AC33: =B33/AB33 -> 182.17924 | AF33: =B33/C33 -> 0.10174607 | AG33: =B33/S33 -> 2.4714238 | AH33: =(K33+L33)/S33 -> 3.0206621 | AI33: =S33/C33 -> 0.041169008 | AJ33: =L33/(K33+L33) -> 0.33747157 | AK33: =O33/S33 -> 0.092829457
A34: 45507 | B34: 23669.17 | C34: 226475 | D34: 0.0512 | E34: 11601 | F34: 104.51 | G34: 1.28 | H34: 384 | I34: 21335.94 | J34: 365 | K34: 20456.7 | L34: 8968.92 | M34: 1.24 | N34: 2.04 | O34: 1909 | P34: 0.1646 | Q34: 12.4 | R34: 56.05 | S34: 13141 | T34: 1556 | U34: 0.4319 | V34: 0.72 | W34: 2517.7 | X34: 0.1231 | Y34: 0.8769 | Z34: 1.09 | AA34: 74.67 | AB34: 186 | AC34: =B34/AB34 -> 127.2536 | AF34: =B34/C34 -> 0.10451118 | AG34: =B34/S34 -> 1.8011696 | AH34: =(K34+L34)/S34 -> 2.2392223 | AI34: =S34/C34 -> 0.058024064 | AJ34: =L34/(K34+L34) -> 0.30479969 | AK34: =O34/S34 -> 0.14527053
A35: 45508 | B35: 28453.73 | C35: 310028 | D35: 0.0469 | E35: 14546 | F35: 91.78 | G35: 1.27 | H35: 459 | I35: 25552.11 | J35: 436 | K35: 24470.31 | L35: 10618.03 | M35: 1.23 | N35: 1.96 | O35: 1878 | P35: 0.1291 | Q35: 15.15 | R35: 56.12 | S35: 18246 | T35: 1457 | U35: 0.4035 | V35: 1.09 | W35: 3645.97 | X35: 0.149 | Y35: 0.851 | Z35: 1.05 | AA35: 77.32 | AB35: 192 | AC35: =B35/AB35 -> 148.19651 | AF35: =B35/C35 -> 0.091777936 | AG35: =B35/S35 -> 1.5594503 | AH35: =(K35+L35)/S35 -> 1.9230703 | AI35: =S35/C35 -> 0.058852749 | AJ35: =L35/(K35+L35) -> 0.3026085 | AK35: =O35/S35 -> 0.10292667
A36: 45509 | B36: 23735.73 | C36: 224746 | D36: 0.0396 | E36: 8904 | F36: 105.61 | G36: 1.17 | H36: 349 | I36: 18915.82 | J36: 341 | K36: 18467.98 | L36: 8786.97 | M36: 1.15 | N36: 2.67 | O36: 642 | P36: 0.0721 | Q36: 36.97 | R36: 54.16 | S36: 9752 | T36: 307 | U36: 0.3771 | V36: 4.99 | W36: 2705.29 | X36: 0.1465 | Y36: 0.8535 | Z36: 0.98 | AA36: 82.7 | AB36: 139 | AC36: =B36/AB36 -> 170.76065 | AF36: =B36/C36 -> 0.10561136 | AG36: =B36/S36 -> 2.4339346 | AH36: =(K36+L36)/S36 -> 2.7948062 | AI36: =S36/C36 -> 0.043391206 | AJ36: =L36/(K36+L36) -> 0.32239905 | AK36: =O36/S36 -> 0.06583265
A37: 45510 | B37: 70638.86 | C37: 860847 | D37: 0.0379 | E37: 32661 | F37: 82.06 | G37: 1.18 | H37: 1077 | I37: 58833.71 | J37: 1047 | K37: 57377.28 | L37: 24349.12 | M37: 1.16 | N37: 2.16 | O37: 2734 | P37: 0.0837 | Q37: 25.84 | R37: 54.8 | S37: 34652 | T37: 1701 | U37: 0.4209 | V37: 1.83 | W37: 7748.28 | X37: 0.135 | Y37: 0.865 | Z37: 1 | AA37: 78.23 | AB37: 407 | AC37: =B37/AB37 -> 173.55985 | AF37: =B37/C37 -> 0.082057392 | AG37: =B37/S37 -> 2.0385219 | AH37: =(K37+L37)/S37 -> 2.3584901 | AI37: =S37/C37 -> 0.040253378 | AJ37: =L37/(K37+L37) -> 0.29793457 | AK37: =O37/S37 -> 0.078898765
A38: 45511 | B38: 586705.92 | C38: 9530722 | D38: 0.038 | E38: 362076 | F38: 61.56 | G38: 1.09 | H38: 8275 | I38: 483742.39 | J38: 8196 | K38: 479864.05 | L38: 158044.83 | M38: 1.09 | N38: 1.62 | O38: 15338 | P38: 0.0424 | Q38: 38.25 | R38: 58.55 | S38: 484162 | T38: 7442 | U38: 0.3897 | V38: 3.93 | W38: 82786.5 | X38: 0.1725 | Y38: 0.8275 | Z38: 0.91 | AA38: 85.86 | AB38: 3588 | AC38: =B38/AB38 -> 163.51893 | AF38: =B38/C38 -> 0.061559441 | AG38: =B38/S38 -> 1.2117967 | AH38: =(K38+L38)/S38 -> 1.3175526 | AI38: =S38/C38 -> 0.050800139 | AJ38: =L38/(K38+L38) -> 0.24775455 | AK38: =O38/S38 -> 0.031679479
A39: 45512 | B39: 73848.19 | C39: 862886 | D39: 0.0484 | E39: 41728 | F39: 85.58 | G39: 1.25 | H39: 1161 | I39: 66909.18 | J39: 1132 | K39: 65313.23 | L39: 25170.27 | M39: 1.23 | N39: 1.77 | O39: 1160 | P39: 0.0278 | Q39: 63.66 | R39: 57.7 | S39: 69187 | T39: 41 | U39: 13.6667 | V39: 0 | W39: 10466.1 | X39: 0.1602 | Y39: 0.8398 | Z39: 1.03 | AA39: 78.06 | AB39: 417 | AC39: =B39/AB39 -> 177.09398 | AF39: =B39/C39 -> 0.085582788 | AG39: =B39/S39 -> 1.0673709 | AH39: =(K39+L39)/S39 -> 1.3078107 | AI39: =S39/C39 -> 0.080180928 | AJ39: =L39/(K39+L39) -> 0.27817525 | AK39: =O39/S39 -> 0.016766155
A40: 45513 | B40: 127284.19 | C40: 1184221 | D40: 0.0418 | E40: 49492 | F40: 107.48 | G40: 1.27 | H40: 1999 | I40: 110260.34 | J40: 1966 | K40: 105761.53 | L40: 51675.99 | M40: 1.24 | N40: 2.57 | O40: 1954 | P40: 0.0395 | Q40: 65.14 | R40: 53.8 | S40: 60064 | T40: 5 | U40: 0 | V40: 0 | W40: 17125.61 | X40: 0.1619 | Y40: 0.8381 | Z40: 1.04 | AA40: 77.61 | AB40: 578 | AC40: =B40/AB40 -> 220.21486 | AF40: =B40/C40 -> 0.10748348 | AG40: =B40/S40 -> 2.1191427 | AH40: =(K40+L40)/S40 -> 2.6211628 | AI40: =S40/C40 -> 0.050720263 | AJ40: =L40/(K40+L40) -> 0.32823173 | AK40: =O40/S40 -> 0.032531966
A41: 45514 | B41: 87943.24 | C41: 831040 | D41: 0.0421 | E41: 35016 | F41: 105.82 | G41: 1.25 | H41: 1385 | I41: 77847.96 | J41: 1368 | K41: 76887.76 | L41: 32433.64 | M41: 1.24 | N41: 2.51 | O41: 1368 | P41: 0.0391 | Q41: 64.29 | R41: 56.2 | S41: 40160 | T41: 9 | U41: 0 | V41: 0 | W41: 10489.12 | X41: 0.1364 | Y41: 0.8636 | Z41: 1.07 | AA41: 75.1 | AB41: 416 | AC41: =B41/AB41 -> 211.40202 | AF41: =B41/C41 -> 0.10582311 | AG41: =B41/S41 -> 2.1898217 | AH41: =(K41+L41)/S41 -> 2.7221464 | AI41: =S41/C41 -> 0.04832499 | AJ41: =L41/(K41+L41) -> 0.29668153 | AK41: =O41/S41 -> 0.034063745
A42: 45515 | B42: 118422.81 | C42: 1396725 | D42: 0.0533 | E42: 74379 | F42: 84.79 | G42: 1.33 | H42: 1986 | I42: 109946.93 | J42: 1960 | K42: 108522.93 | L42: 47620.38 | M42: 1.32 | N42: 1.59 | O42: 1961 | P42: 0.0264 | Q42: 60.39 | R42: 55.37 | S42: 94975 | T42: 7 | U42: 0 | V42: 0 | W42: 17066.04 | X42: 0.1573 | Y42: 0.8427 | Z42: 1.11 | AA42: 72.61 | AB42: 539 | AC42: =B42/AB42 -> 219.70837 | AF42: =B42/C42 -> 0.08478606 | AG42: =B42/S42 -> 1.246884 | AH42: =(K42+L42)/S42 -> 1.6440464 | AI42: =S42/C42 -> 0.067998353 | AJ42: =L42/(K42+L42) -> 0.30497868 | AK42: =O42/S42 -> 0.020647539
A43: 45516 | B43: 83163.35 | C43: 837708 | D43: 0.0467 | E43: 39141 | F43: 99.27 | G43: 1.31 | H43: 1382 | I43: 75288.22 | J43: 1360 | K43: 74550.4 | L43: 33936.9 | M43: 1.3 | N43: 2.12 | O43: 1362 | P43: 0.0348 | Q43: 61.06 | R43: 54.82 | S43: 47955 | T43: 2 | U43: 0 | V43: 0 | W43: 10776.58 | X43: 0.1446 | Y43: 0.8554 | Z43: 1.12 | AA43: 71.75 | AB43: 466 | AC43: =B43/AB43 -> 178.46212 | AF43: =B43/C43 -> 0.099274867 | AG43: =B43/S43 -> 1.7341956 | AH43: =(K43+L43)/S43 -> 2.262273 | AI43: =S43/C43 -> 0.057245484 | AJ43: =L43/(K43+L43) -> 0.3128191 | AK43: =O43/S43 -> 0.028401627
A44: 45517 | B44: 143740.99 | C44: 1708754 | D44: 0.0505 | E44: 86299 | F44: 84.12 | G44: 1.31 | H44: 2386 | I44: 126801.69 | J44: 2355 | K44: 125318.31 | L44: 61278.44 | M44: 1.3 | N44: 1.67 | O44: 2346 | P44: 0.0272 | Q44: 61.27 | R44: 53.21 | S44: 102028 | T44: 0 | U44: 0 | V44: 0 | W44: 15325.58 | X44: 0.1223 | Y44: 0.8777 | Z44: 1.14 | AA44: 70.05 | AB44: 873 | AC44: =B44/AB44 -> 164.65176 | AF44: =B44/C44 -> 0.084120353 | AG44: =B44/S44 -> 1.4088387 | AH44: =(K44+L44)/S44 -> 1.8288779 | AI44: =S44/C44 -> 0.059709004 | AJ44: =L44/(K44+L44) -> 0.32840036 | AK44: =O44/S44 -> 0.022993688
... A142: 45615 | B142: 16129.5 | C142: 189460 | D142: 0.0456 | E142: 8636 | F142: 85.13 | G142: 1.03 | H142: 215 | I142: 12514.1 | J142: 213 | K142: 12410.28 | L142: 4022.27 | M142: 1.02 | N142: 1.87 | O142: 214 | P142: 0.0248 | Q142: 75.37 | R142: 58.26 | S142: 11441 | T142: 0 | U142: 0 | V142: 0 | W142: 1456.09 | X142: 0.1173 | Y142: 0.8827 | Z142: 0.9 | AA142: 85.34 | AB142: 54 | AC142: =B142/AB142 -> 298.69444 | AF142: =B142/C142 -> 0.085134065 | AG142: =B142/S142 -> 1.4097981 | AH142: =(K142+L142)/S142 -> 1.4362862 | AI142: =S142/C142 -> 0.060387417 | AJ142: =L142/(K142+L142) -> 0.24477455 | AK142: =O142/S142 -> 0.018704659

Sheet 新老客销售数据
A1: 新老客销售数据统计
A2: 日期 | B2: 新客销售额 | C2: 新客累计观看人数 | D2: 老客销售额 | E2: 老客累计观看人数 | F2: 总计 | G2: 新客占比 | H2: 老客占比 | I2: 店铺首单新客直接成交金额 | J2: 店铺首单新客订单占比 | K2: 抖音号首单新客直接成交金额 | L2: 抖音号首单新客订单占比 | M2: 品牌首单新客直接成交金额 | N2: 品牌首单新客订单占比
A3: 45477 | F3: =B3+D3 -> 0 | G3: =B3/F3 -> #DIV/0! | H3: =D3/F3 -> #DIV/0!
A4: 45478 | F4: =B4+D4 -> 0 | G4: =B4/F4 -> #DIV/0! | H4: =D4/F4 -> #DIV/0!
A5: 45479 | F5: =B5+D5 -> 0 | G5: =B5/F5 -> #DIV/0! | H5: =D5/F5 -> #DIV/0!
A6: 45480 | F6: =B6+D6 -> 0 | G6: =B6/F6 -> #DIV/0! | H6: =D6/F6 -> #DIV/0!
A7: 45481
A8: 45482
A9: 45483
A10: 45484
A11: 45485
A12: 45486
A13: 45487
A14: 45488
A15: 45489
A16: 45490
A17: 45491
A18: 45492
... A112: 45586

Sheet 每日直播数据总览 
A1: 45573
A2: ①：当天花费共计1.9w，退款前销售额共计7.6w；预估实际投产3.15； ②：当天累计总观看人次64.9万；其中新客累计观看人次60.7万，占比93.52%，老客累计观看人次4.2万，占比6.48%； 当天退款前总销售额7.6万；其中新客销售额2.9万，占比38.15%；老客销售额4.8万，占比61.8%； ③：今天涨粉共计730
A3: 总花费 | B3: =D5 -> 75685.47 | C3: 总成交 | D3: =E5 -> 110394.37 | E3: 今天涨粉儿共计 | F3: =H19+E31+E33+E35 -> 242 | G3: 今日直播时长 | H3: =VLOOKUP(A1,每日转化数据!$B:$AE,4,FALSE) -> 18
A4: 基础整体数据 | D4: 总花费 | E4: 总成交 | F4: 整体roi（退前） | G4: 当天退款金额 | H4: 平均在线人数
D5: =VLOOKUP(A1,每日转化数据!$B:$AE,5,FALSE) -> 75685.47 | E5: =VLOOKUP(A1,每日转化数据!$B:$AE,3,FALSE) -> 110394.37 | F5: =E5/D5 -> 1.458594 | G5: =VLOOKUP(A1,每日转化数据!$B:$AE,9,FALSE) -> 7912.86 | H5: =VLOOKUP(A1,推广数据统计!$A:$BH,30,FALSE) -> 0
D6: 当天退货率 | E6: 实际总成交（退后） | F6: 总场观 | G6: 观看成本 | H6: 实际整体roi（退后）
D7: =VLOOKUP(A1,每日转化数据!$B:$AE,11,FALSE) -> 0.071678112 | E7: =VLOOKUP(A1,每日转化数据!$B:$AE,10,FALSE) -> 102481.51 | F7: =VLOOKUP(A1,每日转化数据!$B:$AE,8,FALSE) -> 48000 | G7: =D5/F7 -> 1.5767806 | H7: =E7/D5 -> 1.3540447
D8: 千川消耗 | E8: 千川成交 | F8: 千川直接roi | G8: 千川当天优惠券成交
D9: =D13 -> 75685.47 | E9: =E13 -> 73734.51 | F9: =D15 -> 1.34 | G9: =F13 -> 27677.06
D10: 自然流成交 | E10: 自然流成交占比 | F10: 千川优惠券成交占比 | G10: 千川成交占比
D11: =E5-G13 -> 8982.8 | E11: =D11/E5 -> 0.081370092 | F11: =H13 -> 0.27291817 | G11: =G13/E5 -> 0.91862991
A12: 推广数据 | B12: 千川 | C12: 千川转化数据 | D12: 千川消耗 | E12: 千川直接成交 | F12: 千川优惠券成交 | G12: 千川总成交（直+券） | H12: 千川优惠券占比
D13: =VLOOKUP(A1,推广数据统计!$A:$BH,2,FALSE) -> 75685.47 | E13: =VLOOKUP(A1,推广数据统计!$A:$BH,11,FALSE) -> 73734.51 | F13: =VLOOKUP(A1,推广数据统计!$A:$BH,12,FALSE) -> 27677.06 | G13: =E13+F13 -> 101411.57 | H13: =F13/G13 -> 0.27291817
D14: 千川直接roi | E14: 千川当天退后gmv | F14: 千川当天退货率 | G14: 千川当天结算roi
D15: =VLOOKUP(A1,推广数据统计!$A:$BH,13,FALSE) -> 1.34 | E15: =(1-F15)*G13 -> 90530.109 | F15: =VLOOKUP(A1,推广数据统计!$A:$BH,24,FALSE) -> 0.1073 | G15: =VLOOKUP(A1,推广数据统计!$A:$BH,26,FALSE) -> 1.2
C16: 千川基础数据 | D16: 展示次数 | E16: 点击率 | F16: 点击次数 | G16: 点击单价 | H16: 平均千次展现费用 | I16: 转化数
D17: =VLOOKUP(A1,推广数据统计!$A:$BH,3,FALSE) -> 798812 | E17: =VLOOKUP(A1,推广数据统计!$A:$BH,4,FALSE) -> 0.0669 | F17: =VLOOKUP(A1,推广数据统计!$A:$BH,5,FALSE) -> 53425 | G17: =VLOOKUP(A1,推广数据统计!$A:$BH,14,FALSE) -> 1.42 | H17: =VLOOKUP(A1,推广数据统计!$A:$BH,6,FALSE) -> 94.75 | I17: =VLOOKUP(A1,推广数据统计!$A:$BH,15,FALSE) -> 1389
D18: 直接成交订单数 | E18: 转化率 | F18: 转化成本 | G18: 广告平均成交金额 | H18: 新增粉丝数 | I18: 直播间观看人次
D19: =VLOOKUP(A1,推广数据统计!$A:$BH,10,FALSE) -> 1395 | E19: =VLOOKUP(A1,推广数据统计!$A:$BH,16,FALSE) -> 0.026 | F19: =VLOOKUP(A1,推广数据统计!$A:$BH,17,FALSE) -> 54.49 | G19: =VLOOKUP(A1,推广数据统计!$A:$BH,18,FALSE) -> 52.86 | H19: =VLOOKUP(A1,推广数据统计!$A:$BH,28,FALSE) -> 242 | I19: =VLOOKUP(A1,推广数据统计!$A:$BH,19,FALSE) -> 59565
C20: 千川数据拆分 | D20: 单次展示成本(曝光成本） | E20: 观看单次成本（场观） | F20: 点击单价 | G20: 曝光观看率 | H20: 均小时流速 | I20: 均小时产出
D21: =VLOOKUP(A1,推广数据统计!$A:$BH,32,FALSE) -> 0.094747538 | E21: =VLOOKUP(A1,推广数据统计!$A:$BH,33,FALSE) -> 1.2706366 | F21: =VLOOKUP(A1,推广数据统计!$A:$BH,14,FALSE) -> 1.42 | G21: =VLOOKUP(A1,推广数据统计!$A:$BH,35,FALSE) -> 0.074566982 | H21: =$D$13/$H$3 -> 4204.7483 | I21: =$E$5/$H$3 -> 6133.0206
D22: 转化成本 | E22: cpm | F22: 千川uv值
D23: =VLOOKUP(A1,推广数据统计!$A:$BH,17,FALSE) -> 54.49 | E23: =VLOOKUP(A1,推广数据统计!$A:$BH,6,FALSE) -> 94.75 | F23: =G13/I19 -> 1.7025362
C24: 触点拆分 | D24: 素材消耗 | E24: 素材占比 | F24: 直投占比 | G24: 通投消耗 | H24: 搜索消耗 | I24: 商品消耗
D25: =VLOOKUP(A1,推广数据统计!$A:$BH,38,FALSE) -> 0 | E25: =VLOOKUP(A1,推广数据统计!$A:$BH,40,FALSE) -> 0 | F25: =VLOOKUP(A1,推广数据统计!$A:$BH,39,FALSE) -> 0 | G25: =VLOOKUP(A1,推广数据统计!$A:$BH,41,FALSE) -> 0 | H25: =VLOOKUP(A1,推广数据统计!$A:$BH,42,FALSE) -> 0 | I25: =VLOOKUP(A1,推广数据统计!$A:$BH,43,FALSE) -> 0
C26: 新老客数据 | D26: 店铺首单新客直接成交金额 | E26: =VLOOKUP(A1,新老客销售数据!$A:$N,9,FALSE) -> 0 | F26: 抖音号首单新客直接成交金额 | G26: =VLOOKUP(A1,新老客销售数据!$A:$N,11,FALSE) -> 0 | H26: 品牌首单新客直接成交金额 | I26: =VLOOKUP(A1,新老客销售数据!$A:$N,13,FALSE) -> 0
D27: 店铺首单新客订单占比 | E27: =VLOOKUP(A1,新老客销售数据!$A:$N,10,FALSE) -> 0 | F27: 抖音号首单新客订单占比 | G27: =VLOOKUP(A1,新老客销售数据!$A:$N,12,FALSE) -> 0 | H27: 品牌首单新客订单占比 | I27: =VLOOKUP(A1,新老客销售数据!$A:$N,14,FALSE) -> 0
B28: 小店随心推 | D28: 花费 | E28: 成交 | F28: roi
D29: =VLOOKUP(A1,推广数据统计!$A:$BH,44,FALSE) -> 0 | E29: =VLOOKUP(A1,推广数据统计!$A:$BH,47,FALSE) -> 0 | F29: =VLOOKUP(A1,推广数据统计!$A:$BH,48,FALSE) -> 0
B30: 抖+ | D30: 花费 | E30: 涨粉 | F30: 涨粉成本
D31: =VLOOKUP(A1,推广数据统计!$A:$BH,41,FALSE) -> 0 | E31: =VLOOKUP(A1,推广数据统计!$A:$BH,42,FALSE) -> 0 | F31: =VLOOKUP(A1,推广数据统计!$A:$BH,43,FALSE) -> 0
B32: 种草通 | D32: 花费 | E32: 涨粉 | F32: 涨粉成本
D33: =VLOOKUP(A1,推广数据统计!$A:$BH,54,FALSE) -> 0 | E33: =VLOOKUP(A1,推广数据统计!$A:$BH,55,FALSE) -> 0 | F33: =VLOOKUP(A1,推广数据统计!$A:$BH,56,FALSE) -> 0
B34: feedslive | D34: 花费 | E34: 涨粉 | F34: 涨粉成本
D35: =VLOOKUP(A1,推广数据统计!$A:$BH,49,FALSE) -> 0 | E35: =VLOOKUP(A1,推广数据统计!$A:$BH,50,FALSE) -> 0 | F35: =VLOOKUP(A1,推广数据统计!$A:$BH,51,FALSE) -> 0
A36: 粉丝数据 | D36: 粉丝量（万） | E36: 粉丝团量（万） | F36: 全天涨粉（万） | G36: 粉丝团增量（万） | H36: 粉丝团占比
D37: =VLOOKUP(A1,每日转化数据!$B:$AE,12,FALSE) -> 0.1351 | E37: =VLOOKUP(A1,每日转化数据!$B:$AE,16,FALSE) -> 0.7057 | F37: =VLOOKUP(A1,每日转化数据!$B:$AE,13,FALSE) -> 0.1123 | G37: =VLOOKUP(A1,每日转化数据!$B:$AE,17,FALSE) -> 0.889 | H37: =E37/D37 -> 5.2235381
A38: 销售目标 | D38: 10月销售目标 | E38: 已完成退前 | F38: 未完成 | G38: 完成率 | I38: 均每日完成目标
D39: 10000000 | E39: =SUM(每日转化数据!D92:D122) -> 4548868.2 | F39: =D39-E39 -> 5451131.8 | G39: =E39/D39 -> 0.45488682 | I39: =F39/(30-10) -> 272556.59

Sheet 数据拆分表
A1: 日期 | B1: 节奏 | C1: 消耗 | D1: 点击率 | E1: 点击次数 | F1: 点击单价 | G1: 平均千次展现费用 | H1: 转化数 | I1: 直接成交订单数 | J1: 转化率 | K1: 转化成本 | L1: 广告平均成交金额 | M1: 直接成交 | N1: 优惠券成交 | O1: 总成交 | P1: 直接roi | Q1: 单次展示成本(曝光成本） | R1: 观看单次成本（场观） | S1: 点击单价 | T1: 转化成本 | U1: cpm | V1: uv值 | W1: 直播间观看人次 | X1: 新增粉丝数
A2: 7.15 | B2: 日常
A3: 8.1 | B3: 日常
A4: 8.7 | B4: 小五大场
A5: 9.15 | B5: 日常
A6: 10.17 | B6: 小五大场
A7: 11.1 | B7: 双十一节点
A8: 11.11
A9: 11.12
A13: 这个表格可以单独做一些重要数据的展现 ：消耗 成交 roi cpm 重要数据

Sheet 大场数据
A1: 抖音号名称 | B1: 抖音号ID | C1: 日期 | D1: 小时区间 | E1: 消耗 | F1: 展示次数 | G1: 点击率 | H1: 点击次数 | I1: 平均千次展现费用 | J1: 7日总支付ROI | K1: 7日总成交订单数 | L1: 7日总成交金额 | M1: 直接成交订单数 | N1: 直接成交金额 | O1: 成交智能优惠券金额 | P1: 直接支付ROI | Q1: 点击单价 | R1: 转化数 | S1: 转化率 | T1: 转化成本 | U1: 广告平均成交金额 | V1: 直播间观看人次 | W1: 有效看播数 | X1: 有效看播率 | Y1: 有效看播成本 | Z1: 直接退款金额(7天) | AA1: 直接退款率(7天) | AB1: 直接成交金额结算率(7天) | AC1: 直接结算ROI(7天) | AD1: 直接结算成本(7天) | AE1: 新增粉丝数 | AF1: 单次展示成本(曝光成本） | AG1: 观看单次成本（场观） | AH1: uv值 | AI1: 曝光观看率 | AJ1: 观看-成交率 | AK1: 单小时消耗占比 | AL1: 单小时成交占比 | AM1: 大场单小时消耗占比 | AN1: 大场单小时成交占比
A2: 雕牌官方旗舰店 | B2: naaisijituan73 | C2: 全部 | D2: 全部 | E2: 586705.92 | F2: 9530722 | G2: 0.038 | H2: 362076 | I2: 61.56 | J2: 1.09 | K2: 8275 | L2: 483742.39 | M2: 8196 | N2: 479864.05 | O2: 158044.83 | P2: 1.09 | Q2: 1.62 | R2: 15338 | S2: 0.0424 | T2: 38.25 | U2: 58.55 | V2: 484162 | W2: 7442 | X2: 0.3897 | Y2: 3.93 | Z2: 82786.5 | AA2: 0.1725 | AB2: 0.8275 | AC2: 0.91 | AD2: 85.86 | AE2: 3588
A3: 雕牌官方旗舰店 | B3: naaisijituan73 | C3: 45511 | D3: 全部 | E3: 586705.92 | F3: 9530722 | G3: 0.038 | H3: 362076 | I3: 61.56 | J3: 1.09 | K3: 8275 | L3: 483742.39 | M3: 8196 | N3: 479864.05 | O3: 158044.83 | P3: 1.09 | Q3: 1.62 | R3: 15338 | S3: 0.0424 | T3: 38.25 | U3: 58.55 | V3: 484162 | W3: 7442 | X3: 0.3897 | Y3: 3.93 | Z3: 82786.5 | AA3: 0.1725 | AB3: 0.8275 | AC3: 0.91 | AD3: 85.86 | AE3: 3588
A4: 雕牌官方旗舰店 | B4: naaisijituan73 | C4: 45511 | D4: 00:00 ~ 01:00 | E4: 178.51 | F4: 6480 | G4: 0.0315 | H4: 204 | I4: 27.55 | J4: 1.62 | K4: 5 | L4: 269.3 | M4: 3 | N4: 219.7 | O4: 20 | P4: 1.34 | Q4: 0.88 | R4: 9 | S4: 0.0441 | T4: 19.83 | U4: 73.23 | V4: 256 | W4: 9 | X4: 0.8182 | Y4: 0.09 | Z4: 139.8 | AA4: 0.6363 | AB4: 0.3637 | AC4: 0.45 | AD4: 178.51 | AE4: 5 | AF4: =E4/F4 -> 0.02754784 | AG4: =E4/V4 -> 0.69730469 | AH4: =(N4+O4)/V4 -> 0.93632812 | AI4: =V4/F4 -> 0.039506173 | AJ4: =R4/V4 -> 0.03515625 | AK4: =E4/$E$3 -> 0.00030425805 | AL4: =(N4+O4)/($N$3+$O$3) -> 0.000375759
A5: 雕牌官方旗舰店 | B5: naaisijituan73 | C5: 45511 | D5: 01:00 ~ 02:00 | E5: 0.09 | F5: 238 | G5: 0.0378 | H5: 9 | I5: 0.38 | J5: 0 | K5: 0 | L5: 0 | M5: 0 | N5: 0 | O5: 0 | P5: 0 | Q5: 0.01 | R5: 0 | S5: 0 | T5: 0 | U5: 0 | V5: 33 | W5: 0 | X5: 0 | Y5: 0 | Z5: 0 | AA5: 0 | AB5: 0 | AC5: 0 | AD5: 0 | AE5: 1 | AF5: =E5/F5 -> 0.00037815126 | AG5: =E5/V5 -> 0.0027272727 | AH5: =(N5+O5)/V5 -> 0 | AI5: =V5/F5 -> 0.13865546 | AJ5: =R5/V5 -> 0 | AK5: =E5/$E$3 -> 1.5339883e-07 | AL5: =(N5+O5)/($N$3+$O$3) -> 0
A6: 雕牌官方旗舰店 | B6: naaisijituan73 | C6: 45511 | D6: 02:00 ~ 03:00 | E6: 0 | F6: 63 | G6: 0.0159 | H6: 1 | I6: 0 | J6: 0 | K6: 0 | L6: 0 | M6: 0 | N6: 0 | O6: 0 | P6: 0 | Q6: 0 | R6: 0 | S6: 0 | T6: 0 | U6: 0 | V6: 16 | W6: 0 | X6: 0 | Y6: 0 | Z6: 0 | AA6: 0 | AB6: 0 | AC6: 0 | AD6: 0 | AE6: 0 | AF6: =E6/F6 -> 0 | AG6: =E6/V6 -> 0 | AH6: =(N6+O6)/V6 -> 0 | AI6: =V6/F6 -> 0.25396825 | AJ6: =R6/V6 -> 0 | AK6: =E6/$E$3 -> 0 | AL6: =(N6+O6)/($N$3+$O$3) -> 0
A7: 雕牌官方旗舰店 | B7: naaisijituan73 | C7: 45511 | D7: 03:00 ~ 04:00 | E7: 0 | F7: 6 | G7: 0 | H7: 0 | I7: 0 | J7: 0 | K7: 0 | L7: 0 | M7: 0 | N7: 0 | O7: 0 | P7: 0 | Q7: 0 | R7: 0 | S7: 0 | T7: 0 | U7: 0 | V7: 8 | W7: 0 | X7: 0 | Y7: 0 | Z7: 0 | AA7: 0 | AB7: 0 | AC7: 0 | AD7: 0 | AE7: 0 | AF7: =E7/F7 -> 0 | AG7: =E7/V7 -> 0 | AH7: =(N7+O7)/V7 -> 0 | AI7: =V7/F7 -> 1.3333333 | AJ7: =R7/V7 -> 0 | AK7: =E7/$E$3 -> 0 | AL7: =(N7+O7)/($N$3+$O$3) -> 0
A8: 雕牌官方旗舰店 | B8: naaisijituan73 | C8: 45511 | D8: 04:00 ~ 05:00 | E8: 0 | F8: 8 | G8: 0 | H8: 0 | I8: 0 | J8: 0 | K8: 0 | L8: 0 | M8: 0 | N8: 0 | O8: 0 | P8: 0 | Q8: 0 | R8: 0 | S8: 0 | T8: 0 | U8: 0 | V8: 11 | W8: 0 | X8: 0 | Y8: 0 | Z8: 0 | AA8: 0 | AB8: 0 | AC8: 0 | AD8: 0 | AE8: 0 | AF8: =E8/F8 -> 0 | AG8: =E8/V8 -> 0 | AH8: =(N8+O8)/V8 -> 0 | AI8: =V8/F8 -> 1.375 | AJ8: =R8/V8 -> 0 | AK8: =E8/$E$3 -> 0 | AL8: =(N8+O8)/($N$3+$O$3) -> 0
A9: 雕牌官方旗舰店 | B9: naaisijituan73 | C9: 45511 | D9: 05:00 ~ 06:00 | E9: 0 | F9: 9 | G9: 0 | H9: 0 | I9: 0 | J9: 0 | K9: 0 | L9: 0 | M9: 0 | N9: 0 | O9: 0 | P9: 0 | Q9: 0 | R9: 0 | S9: 0 | T9: 0 | U9: 0 | V9: 21 | W9: 0 | X9: 0 | Y9: 0 | Z9: 0 | AA9: 0 | AB9: 0 | AC9: 0 | AD9: 0 | AE9: 0 | AF9: =E9/F9 -> 0 | AG9: =E9/V9 -> 0 | AH9: =(N9+O9)/V9 -> 0 | AI9: =V9/F9 -> 2.3333333 | AJ9: =R9/V9 -> 0 | AK9: =E9/$E$3 -> 0 | AL9: =(N9+O9)/($N$3+$O$3) -> 0
A10: 雕牌官方旗舰店 | B10: naaisijituan73 | C10: 45511 | D10: 06:00 ~ 07:00 | E10: 4582.56 | F10: 53252 | G10: 0.0737 | H10: 3923 | I10: 86.05 | J10: 1.02 | K10: 62 | L10: 3428.9 | M10: 60 | N10: 3405.2 | O10: 1246 | P10: 1.01 | Q10: 1.17 | R10: 110 | S10: 0.028 | T10: 41.66 | U10: 56.75 | V10: 4068 | W10: 46 | X10: 0.3966 | Y10: 2.15 | Z10: 656.7 | AA10: 0.1929 | AB10: 0.8071 | AC10: 0.83 | AD10: 95.47 | AE10: 42 | AF10: =E10/F10 -> 0.086054233 | AG10: =E10/V10 -> 1.1264897 | AH10: =(N10+O10)/V10 -> 1.1433628 | AI10: =V10/F10 -> 0.076391497 | AJ10: =R10/V10 -> 0.027040315 | AK10: =E10/$E$3 -> 0.0078106592 | AL10: =(N10+O10)/($N$3+$O$3) -> 0.0072913235
A11: 雕牌官方旗舰店 | B11: naaisijituan73 | C11: 45511 | D11: 07:00 ~ 08:00 | E11: 6703.19 | F11: 64140 | G11: 0.0478 | H11: 3069 | I11: 104.51 | J11: 1.33 | K11: 115 | L11: 6329.51 | M11: 113 | N11: 6260.11 | O11: 2584.99 | P11: 1.32 | Q11: 2.18 | R11: 194 | S11: 0.0632 | T11: 34.55 | U11: 55.4 | V11: 3533 | W11: 55 | X11: 0.309 | Y11: 2.05 | Z11: 1457.5 | AA11: 0.2328 | AB11: 0.7672 | AC11: 1.01 | AD11: 77.94 | AE11: 46 | AF11: =E11/F11 -> 0.10450873 | AG11: =E11/V11 -> 1.8973082 | AH11: =(N11+O11)/V11 -> 2.5035664 | AI11: =V11/F11 -> 0.055082632 | AJ11: =R11/V11 -> 0.054910841 | AK11: =E11/$E$3 -> 0.011425128 | AL11: =(N11+O11)/($N$3+$O$3) -> 0.013865773
A12: 雕牌官方旗舰店 | B12: naaisijituan73 | C12: 45511 | D12: 08:00 ~ 09:00 | E12: 10505.23 | F12: 114430 | G12: 0.0601 | H12: 6880 | I12: 91.8 | J12: 1.38 | K12: 182 | L12: 10183.03 | M12: 180 | N12: 9923.53 | O12: 4360.03 | P12: 1.36 | Q12: 1.53 | R12: 304 | S12: 0.0442 | T12: 34.56 | U12: 55.13 | V12: 7620 | W12: 134 | X12: 0.3592 | Y12: 0.9 | Z12: 1978 | AA12: 0.1993 | AB12: 0.8007 | AC12: 1.09 | AD12: 73.46 | AE12: 80 | AF12: =E12/F12 -> 0.091804859 | AG12: =E12/V12 -> 1.3786391 | AH12: =(N12+O12)/V12 -> 1.8744829 | AI12: =V12/F12 -> 0.066590929 | AJ12: =R12/V12 -> 0.039895013 | AK12: =E12/$E$3 -> 0.017905444 | AL12: =(N12+O12)/($N$3+$O$3) -> 0.022391223
A13: 雕牌官方旗舰店 | B13: naaisijituan73 | C13: 45511 | D13: 09:00 ~ 10:00 | E13: 7090.59 | F13: 78902 | G13: 0.0508 | H13: 4010 | I13: 89.87 | J13: 1.28 | K13: 116 | L13: 6413.36 | M13: 113 | N13: 6249.26 | O13: 2636.53 | P13: 1.25 | Q13: 1.77 | R13: 344 | S13: 0.0858 | T13: 20.61 | U13: 55.3 | V13: 4811 | W13: 243 | X13: 0.3951 | Y13: 0.48 | Z13: 1194.3 | AA13: 0.1911 | AB13: 0.8089 | AC13: 1.01 | AD13: 78.78 | AE13: 63 | AF13: =E13/F13 -> 0.089865783 | AG13: =E13/V13 -> 1.4738287 | AH13: =(N13+O13)/V13 -> 1.8469736 | AI13: =V13/F13 -> 0.060974373 | AJ13: =R13/V13 -> 0.071502806 | AK13: =E13/$E$3 -> 0.012085424 | AL13: =(N13+O13)/($N$3+$O$3) -> 0.01392956
A14: 雕牌官方旗舰店 | B14: naaisijituan73 | C14: 45511 | D14: 10:00 ~ 11:00 | E14: 4548.28 | F14: 48910 | G14: 0.0516 | H14: 2524 | I14: 92.99 | J14: 1.36 | K14: 82 | L14: 4222.9 | M14: 77 | N14: 4148.28 | O14: 1948.02 | P14: 1.34 | Q14: 1.8 | R14: 266 | S14: 0.1054 | T14: 17.1 | U14: 53.87 | V14: 3032 | W14: 190 | X14: 0.446 | Y14: 0.67 | Z14: 615.99 | AA14: 0.1485 | AB14: 0.8515 | AC14: 1.14 | AD14: 71.07 | AE14: 32 | AF14: =E14/F14 -> 0.092992844 | AG14: =E14/V14 -> 1.5000923 | AH14: =(N14+O14)/V14 -> 2.010653 | AI14: =V14/F14 -> 0.061991413 | AJ14: =R14/V14 -> 0.087730871 | AK14: =E14/$E$3 -> 0.0077522313 | AL14: =(N14+O14)/($N$3+$O$3) -> 0.0095566941
A15: 雕牌官方旗舰店 | B15: naaisijituan73 | C15: 45511 | D15: 11:00 ~ 12:00 | E15: 6766.54 | F15: 74883 | G15: 0.0501 | H15: 3754 | I15: 90.36 | J15: 1.13 | K15: 102 | L15: 5423.18 | M15: 100 | N15: 5329.48 | O15: 2255 | P15: 1.12 | Q15: 1.8 | R15: 263 | S15: 0.0701 | T15: 25.73 | U15: 53.29 | V15: 4499 | W15: 167 | X15: 0.4501 | Y15: 0.82 | Z15: 883.59 | AA15: 0.1658 | AB15: 0.8342 | AC15: 0.93 | AD15: 82.52 | AE15: 40 | AF15: =E15/F15 -> 0.090361497 | AG15: =E15/V15 -> 1.5040098 | AH15: =(N15+O15)/V15 -> 1.6858146 | AI15: =V15/F15 -> 0.060080392 | AJ15: =R15/V15 -> 0.058457435 | AK15: =E15/$E$3 -> 0.011533103 | AL15: =(N15+O15)/($N$3+$O$3) -> 0.011889598
... A23: 雕牌官方旗舰店 | B23: naaisijituan73 | C23: 45511 | D23: 19:00 ~ 20:00 | E23: 7417.56 | F23: 112007 | G23: 0.0313 | H23: 3511 | I23: 66.22 | J23: 1.03 | K23: 102 | L23: 5807.9 | M23: 99 | N23: 5707.2 | O23: 1800.99 | P23: 1.01 | Q23: 2.11 | R23: 145 | S23: 0.0413 | T23: 51.16 | U23: 57.65 | V23: 4316 | W23: 30 | X23: 0.5 | Y23: 6.76 | Z23: 812.01 | AA23: 0.1423 | AB23: 0.8577 | AC23: 0.87 | AD23: 87.27 | AE23: 44 | AF23: =E23/F23 -> 0.066224075 | AG23: =E23/V23 -> 1.7186191 | AH23: =(N23+O23)/V23 -> 1.7396177 | AI23: =V23/F23 -> 0.038533306 | AJ23: =R23/V23 -> 0.033595922 | AK23: =E23/$E$3 -> 0.012642722 | AL23: =(N23+O23)/($N$3+$O$3) -> 0.011770004
A24: 雕牌官方旗舰店 | B24: naaisijituan73 | C24: 45511 | D24: 20:00 ~ 21:00 | E24: 30626.6 | F24: 498532 | G24: 0.0373 | H24: 18578 | I24: 61.43 | J24: 1.41 | K24: 509 | L24: 35967.99 | M24: 504 | N24: 35668.89 | O24: 7187.05 | P24: 1.4 | Q24: 1.65 | R24: 1109 | S24: 0.0597 | T24: 27.62 | U24: 70.77 | V24: 23874 | W24: 610 | X24: 0.3421 | Y24: 8.07 | Z24: 11180.59 | AA24: 0.3135 | AB24: 0.6865 | AC24: 0.98 | AD24: 75.07 | AE24: 211 | AF24: =E24/F24 -> 0.061433569 | AG24: =E24/V24 -> 1.2828433 | AH24: =(N24+O24)/V24 -> 1.7950884 | AI24: =V24/F24 -> 0.047888601 | AJ24: =R24/V24 -> 0.046452207 | AK24: =E24/$E$3 -> 0.052200939 | AL24: =(N24+O24)/($N$3+$O$3) -> 0.067181915 | AM24: =E24/(SUM($E$24:$E$27)) -> 0.063204363 | AN24: =(N24+O24)/SUM($N$24:$O$27) -> 0.083216303
A25: 雕牌官方旗舰店 | B25: naaisijituan73 | C25: 45511 | D25: 21:00 ~ 22:00 | E25: 167779.99 | F25: 2696707 | G25: 0.0418 | H25: 112816 | I25: 62.22 | J25: 1.01 | K25: 2228 | L25: 130831 | M25: 2214 | N25: 130025.6 | O25: 38369.76 | P25: 1 | Q25: 1.49 | R25: 4543 | S25: 0.0403 | T25: 36.93 | U25: 58.73 | V25: 149087 | W25: 2368 | X25: 0.3532 | Y25: 6.88 | Z25: 22264.25 | AA25: 0.1712 | AB25: 0.8288 | AC25: 0.84 | AD25: 91.48 | AE25: 1014 | AF25: =E25/F25 -> 0.062216618 | AG25: =E25/V25 -> 1.1253831 | AH25: =(N25+O25)/V25 -> 1.1295107 | AI25: =V25/F25 -> 0.055284834 | AJ25: =R25/V25 -> 0.03047214 | AK25: =E25/$E$3 -> 0.28596949 | AL25: =(N25+O25)/($N$3+$O$3) -> 0.26398027 | AM25: =E25/(SUM($E$24:$E$27)) -> 0.34624893 | AN25: =(N25+O25)/SUM($N$24:$O$27) -> 0.32698476
A26: 雕牌官方旗舰店 | B26: naaisijituan73 | C26: 45511 | D26: 22:00 ~ 23:00 | E26: 204728.84 | F26: 3383566 | G26: 0.0398 | H26: 134579 | I26: 60.51 | J26: 1.12 | K26: 2956 | L26: 168376 | M26: 2936 | N26: 167422.3 | O26: 60016.51 | P26: 1.11 | Q26: 1.52 | R26: 5117 | S26: 0.038 | T26: 40.01 | U26: 57.02 | V26: 192680 | W26: 2300 | X26: 0.4336 | Y26: 1.94 | Z26: 25876.07 | AA26: 0.1546 | AB26: 0.8454 | AC26: 0.94 | AD26: 82.52 | AE26: 1316 | AF26: =E26/F26 -> 0.060506826 | AG26: =E26/V26 -> 1.0625329 | AH26: =(N26+O26)/V26 -> 1.1803966 | AI26: =V26/F26 -> 0.056945838 | AJ26: =R26/V26 -> 0.026556986 | AK26: =E26/$E$3 -> 0.34894627 | AL26: =(N26+O26)/($N$3+$O$3) -> 0.35653808 | AM26: =E26/(SUM($E$24:$E$27)) -> 0.42250057 | AN26: =(N26+O26)/SUM($N$24:$O$27) -> 0.44163346
A27: 雕牌官方旗舰店 | B27: naaisijituan73 | C27: 45511 | D27: 23:00 ~ 24:00 | E27: 81429.22 | F27: 1633056 | G27: 0.023 | H27: 37486 | I27: 49.86 | J27: 0.94 | K27: 977 | L27: 60365.7 | M27: 968 | N27: 59755.7 | O27: 16548.71 | P27: 0.94 | Q27: 2.17 | R27: 1779 | S27: 0.0475 | T27: 45.77 | U27: 61.73 | V27: 48677 | W27: 950 | X27: 0.4156 | Y27: 1.76 | Z27: 7933.92 | AA27: 0.1328 | AB27: 0.8672 | AC27: 0.82 | AD27: 97.52 | AE27: 359 | AF27: =E27/F27 -> 0.049863091 | AG27: =E27/V27 -> 1.672848 | AH27: =(N27+O27)/V27 -> 1.567566 | AI27: =V27/F27 -> 0.029807306 | AJ27: =R27/V27 -> 0.036547035 | AK27: =E27/$E$3 -> 0.13879052 | AL27: =(N27+O27)/($N$3+$O$3) -> 0.11961647 | AM27: =E27/(SUM($E$24:$E$27)) -> 0.16804614 | AN27: =(N27+O27)/SUM($N$24:$O$27) -> 0.14816548
A28: 抖音号名称 | B28: 抖音号ID | C28: 日期 | D28: 小时区间 | E28: 消耗 | F28: 展示次数 | G28: 点击率 | H28: 点击次数 | I28: 平均千次展现费用 | J28: 7日总支付ROI | K28: 7日总成交订单数 | L28: 7日总成交金额 | M28: 直接成交订单数 | N28: 直接成交金额 | O28: 成交智能优惠券金额 | P28: 直接支付ROI | Q28: 点击单价 | R28: 转化数 | S28: 转化率 | T28: 转化成本 | U28: 广告平均成交金额 | V28: 直播间观看人次 | W28: 有效看播数 | X28: 有效看播率 | Y28: 有效看播成本 | Z28: 直接退款金额(7天) | AA28: 直接退款率(7天) | AB28: 直接成交金额结算率(7天) | AC28: 直接结算ROI(7天) | AD28: 直接结算成本(7天) | AE28: 新增粉丝数 | AF28: 单次展示成本(曝光成本） | AG28: 观看单次成本（场观） | AH28: uv值 | AI28: 曝光观看率 | AJ28: 观看-成交率 | AK28: 单小时消耗占比 | AL28: 单小时成交占比 | AM28: 大场单小时消耗占比 | AN28: 大场单小时成交占比
A29: 雕牌官方旗舰店 | B29: naaisijituan73 | C29: 全部 | D29: 全部 | E29: 1325915 | F29: 13704777 | G29: 0.053 | H29: 725932 | I29: 96.75 | J29: 1.27 | K29: 23176 | L29: 1164345.2 | M29: 22976 | N29: 1153262.9 | O29: 523880.61 | P29: 1.26 | Q29: 1.83 | R29: 23838 | S29: 0.0328 | T29: 55.62 | U29: 50.19 | V29: 798561 | W29: 1279 | X29: 0.4421 | Y29: 1.08 | Z29: 157479.28 | AA29: 0.1366 | AB29: 0.8634 | AC29: 1.1 | AD29: 66.54 | AE29: 6527
A30: 雕牌官方旗舰店 | B30: naaisijituan73 | C30: 45582 | D30: 全部 | E30: 1071632.9 | F30: 11139532 | G30: 0.0516 | H30: 574933 | I30: 96.2 | J30: 1.28 | K30: 18952 | L30: 946139.17 | M30: 18797 | N30: 937959.25 | O30: 420798.41 | P30: 1.27 | Q30: 1.86 | R30: 19653 | S30: 0.0342 | T30: 54.53 | U30: 49.9 | V30: 622103 | W30: 1211 | X30: 0.4402 | Y30: 1.13 | Z30: 135085.69 | AA30: 0.144 | AB30: 0.856 | AC30: 1.09 | AD30: 66.12 | AE30: 5502
A31: 雕牌官方旗舰店 | B31: naaisijituan73 | C31: 45582 | D31: 00:00 ~ 01:00 | E31: 50.52 | F31: 1870 | G31: 0.0225 | H31: 42 | I31: 27.02 | J31: 0 | K31: 0 | L31: 0 | M31: 0 | N31: 0 | O31: 0 | P31: 0 | Q31: 1.2 | R31: 0 | S31: 0 | T31: 0 | U31: 0 | V31: 46 | W31: 0 | X31: 0 | Y31: 0 | Z31: 0 | AA31: 0 | AB31: 0 | AC31: 0 | AD31: 0 | AE31: 0 | AF31: =E31/F31 -> 0.027016043 | AG31: =E31/V31 -> 1.0982609 | AH31: =(N31+O31)/V31 -> 0 | AI31: =V31/F31 -> 0.02459893 | AJ31: =R31/V31 -> 0 | AK31: =E31/$E$30 -> 4.7143007e-05 | AL31: =(N31+O31)/SUM($N$30:$O$30) -> 0
A32: 雕牌官方旗舰店 | B32: naaisijituan73 | C32: 45582 | D32: 01:00 ~ 02:00 | E32: 0.64 | F32: 171 | G32: 0.0175 | H32: 3 | I32: 3.74 | J32: 0 | K32: 0 | L32: 0 | M32: 0 | N32: 0 | O32: 0 | P32: 0 | Q32: 0.21 | R32: 0 | S32: 0 | T32: 0 | U32: 0 | V32: 12 | W32: 0 | X32: 0 | Y32: 0 | Z32: 0 | AA32: 0 | AB32: 0 | AC32: 0 | AD32: 0 | AE32: 0 | AF32: =E32/F32 -> 0.0037426901 | AG32: =E32/V32 -> 0.053333333 | AH32: =(N32+O32)/V32 -> 0 | AI32: =V32/F32 -> 0.070175439 | AJ32: =R32/V32 -> 0 | AK32: =E32/$E$30 -> 5.9721941e-07 | AL32: =(N32+O32)/SUM($N$30:$O$30) -> 0
A33: 雕牌官方旗舰店 | B33: naaisijituan73 | C33: 45582 | D33: 02:00 ~ 03:00 | E33: 0.22 | F33: 68 | G33: 0.0147 | H33: 1 | I33: 3.24 | J33: 0 | K33: 0 | L33: 0 | M33: 0 | N33: 0 | O33: 0 | P33: 0 | Q33: 0.22 | R33: 0 | S33: 0 | T33: 0 | U33: 0 | V33: 6 | W33: 0 | X33: 0 | Y33: 0 | Z33: 0 | AA33: 0 | AB33: 0 | AC33: 0 | AD33: 0 | AE33: 0 | AF33: =E33/F33 -> 0.0032352941 | AG33: =E33/V33 -> 0.036666667 | AH33: =(N33+O33)/V33 -> 0 | AI33: =V33/F33 -> 0.088235294 | AJ33: =R33/V33 -> 0 | AK33: =E33/$E$30 -> 2.0529417e-07 | AL33: =(N33+O33)/SUM($N$30:$O$30) -> 0
A34: 雕牌官方旗舰店 | B34: naaisijituan73 | C34: 45582 | D34: 03:00 ~ 04:00 | E34: 0 | F34: 13 | G34: 0 | H34: 0 | I34: 0 | J34: 0 | K34: 0 | L34: 0 | M34: 0 | N34: 0 | O34: 0 | P34: 0 | Q34: 0 | R34: 0 | S34: 0 | T34: 0 | U34: 0 | V34: 1 | W34: 0 | X34: 0 | Y34: 0 | Z34: 0 | AA34: 0 | AB34: 0 | AC34: 0 | AD34: 0 | AE34: 0 | AF34: =E34/F34 -> 0 | AG34: =E34/V34 -> 0 | AH34: =(N34+O34)/V34 -> 0 | AI34: =V34/F34 -> 0.076923077 | AJ34: =R34/V34 -> 0 | AK34: =E34/$E$30 -> 0 | AL34: =(N34+O34)/SUM($N$30:$O$30) -> 0
A35: 雕牌官方旗舰店 | B35: naaisijituan73 | C35: 45582 | D35: 04:00 ~ 05:00 | E35: 0 | F35: 7 | G35: 0 | H35: 0 | I35: 0 | J35: 0 | K35: 0 | L35: 0 | M35: 0 | N35: 0 | O35: 0 | P35: 0 | Q35: 0 | R35: 0 | S35: 0 | T35: 0 | U35: 0 | V35: 3 | W35: 0 | X35: 0 | Y35: 0 | Z35: 0 | AA35: 0 | AB35: 0 | AC35: 0 | AD35: 0 | AE35: 0 | AF35: =E35/F35 -> 0 | AG35: =E35/V35 -> 0 | AH35: =(N35+O35)/V35 -> 0 | AI35: =V35/F35 -> 0.42857143 | AJ35: =R35/V35 -> 0 | AK35: =E35/$E$30 -> 0 | AL35: =(N35+O35)/SUM($N$30:$O$30) -> 0
A36: 雕牌官方旗舰店 | B36: naaisijituan73 | C36: 45582 | D36: 05:00 ~ 06:00 | E36: 0 | F36: 19 | G36: 0 | H36: 0 | I36: 0 | J36: 0 | K36: 0 | L36: 0 | M36: 0 | N36: 0 | O36: 0 | P36: 0 | Q36: 0 | R36: 0 | S36: 0 | T36: 0 | U36: 0 | V36: 10 | W36: 0 | X36: 0 | Y36: 0 | Z36: 0 | AA36: 0 | AB36: 0 | AC36: 0 | AD36: 0 | AE36: 0 | AF36: =E36/F36 -> 0 | AG36: =E36/V36 -> 0 | AH36: =(N36+O36)/V36 -> 0 | AI36: =V36/F36 -> 0.52631579 | AJ36: =R36/V36 -> 0 | AK36: =E36/$E$30 -> 0 | AL36: =(N36+O36)/SUM($N$30:$O$30) -> 0
A37: 雕牌官方旗舰店 | B37: naaisijituan73 | C37: 45582 | D37: 06:00 ~ 07:00 | E37: 11777.49 | F37: 135361 | G37: 0.0672 | H37: 9091 | I37: 87.01 | J37: 1.37 | K37: 211 | L37: 11635 | M37: 209 | N37: 11495.2 | O37: 4467.05 | P37: 1.36 | Q37: 1.3 | R37: 235 | S37: 0.0258 | T37: 50.12 | U37: 55 | V37: 10050 | W37: 0 | X37: 0 | Y37: 0 | Z37: 1378.66 | AA37: 0.1199 | AB37: 0.8801 | AC37: 1.19 | AD37: 64.36 | AE37: 69 | AF37: =E37/F37 -> 0.087008001 | AG37: =E37/V37 -> 1.1718896 | AH37: =(N37+O37)/V37 -> 1.5882836 | AI37: =V37/F37 -> 0.074245905 | AJ37: =R37/V37 -> 0.023383085 | AK37: =E37/$E$30 -> 0.010990228 | AL37: =(N37+O37)/SUM($N$30:$O$30) -> 0.01174768
A38: 雕牌官方旗舰店 | B38: naaisijituan73 | C38: 45582 | D38: 07:00 ~ 08:00 | E38: 11074.41 | F38: 126436 | G38: 0.0619 | H38: 7829 | I38: 87.59 | J38: 1.51 | K38: 218 | L38: 12090.76 | M38: 216 | N38: 12080.85 | O38: 4632.98 | P38: 1.51 | Q38: 1.41 | R38: 201 | S38: 0.0257 | T38: 55.1 | U38: 55.93 | V38: 8534 | W38: 0 | X38: 0 | Y38: 0 | Z38: 1479.45 | AA38: 0.1225 | AB38: 0.8775 | AC38: 1.33 | AD38: 58.29 | AE38: 65 | AF38: =E38/F38 -> 0.087589057 | AG38: =E38/V38 -> 1.297681 | AH38: =(N38+O38)/V38 -> 1.9584989 | AI38: =V38/F38 -> 0.067496599 | AJ38: =R38/V38 -> 0.023552847 | AK38: =E38/$E$30 -> 0.010334145 | AL38: =(N38+O38)/SUM($N$30:$O$30) -> 0.012300817
A39: 雕牌官方旗舰店 | B39: naaisijituan73 | C39: 45582 | D39: 08:00 ~ 09:00 | E39: 35071.05 | F39: 286598 | G39: 0.0685 | H39: 19631 | I39: 122.37 | J39: 1.07 | K39: 488 | L39: 24464.43 | M39: 482 | N39: 24366.23 | O39: 13089.67 | P39: 1.07 | Q39: 1.79 | R39: 521 | S39: 0.0265 | T39: 67.31 | U39: 50.55 | V39: 20123 | W39: 0 | X39: 0 | Y39: 0 | Z39: 2727.76 | AA39: 0.1119 | AB39: 0.8881 | AC39: 0.94 | AD39: 83.5 | AE39: 167 | AF39: =E39/F39 -> 0.12237018 | AG39: =E39/V39 -> 1.7428341 | AH39: =(N39+O39)/V39 -> 1.8613477 | AI39: =V39/F39 -> 0.07021333 | AJ39: =R39/V39 -> 0.025890772 | AK39: =E39/$E$30 -> 0.032726737 | AL39: =(N39+O39)/SUM($N$30:$O$30) -> 0.027566284
A40: 雕牌官方旗舰店 | B40: naaisijituan73 | C40: 45582 | D40: 09:00 ~ 10:00 | E40: 25817.61 | F40: 255708 | G40: 0.0549 | H40: 14026 | I40: 100.97 | J40: 1.35 | K40: 449 | L40: 22989.34 | M40: 442 | N40: 22562 | O40: 11791.76 | P40: 1.33 | Q40: 1.84 | R40: 423 | S40: 0.0302 | T40: 61.03 | U40: 51.05 | V40: 15077 | W40: 0 | X40: 0 | Y40: 0 | Z40: 2023.31 | AA40: 0.0897 | AB40: 0.9103 | AC40: 1.22 | AD40: 64.22 | AE40: 124 | AF40: =E40/F40 -> 0.1009652 | AG40: =E40/V40 -> 1.7123838 | AH40: =(N40+O40)/V40 -> 2.2785541 | AI40: =V40/F40 -> 0.058961785 | AJ40: =R40/V40 -> 0.028055979 | AK40: =E40/$E$30 -> 0.02409184 | AL40: =(N40+O40)/SUM($N$30:$O$30) -> 0.025283213
